Workbook

Sheet คู่มือ
A1: คู่มือการกรอกแบบสำรวจ Approval Matrix
A3: วัตถุประสงค์
A4: ทบทวนว่ากระบวนการใดควร คง / ตัด การกลั่นกรองผ่านเลขานุการคณะ (D2) หรือเปลี่ยนให้หน่วยงานผู้เชี่ยวชาญตรวจแทน โดยใช้ข้อมูลจริงจากหัวหน้างาน เพื่อลดขั้นตอนและ Lead Time โดยยังคงการควบคุมภายในให้สอดคล้องกับระดับความเสี่ยง
A6: ระดับในสาย Approval
A7: ระดับ | B7: ตำแหน่ง | C7: บทบาทหลัก
A8: A1 | B8: ผู้ปฏิบัติ | C8: เจ้าของเรื่อง จัดทำข้อมูล เอกสาร และรายละเอียดเพื่อเสนอขออนุมัติ
A9: D1 | B9: หัวหน้างาน | C9: ควบคุมงานประจำ รับรองความถูกต้องและความจำเป็นของงาน
A10: D2 | B10: เลขานุการคณะ | C10: กำกับดูแลภาพรวมสำนักงาน กลั่นกรองเรื่องที่มีความเสี่ยงหรือกระทบหลายหน่วยงาน ◀ จุดที่สำรวจ
A11: A2 | B11: หน่วยงานเฉพาะทาง | C11: กำกับดูแลระเบียบ ข้อบังคับ มาตรฐาน หรือความถูกต้องทางวิชาชีพในเรื่องนั้นโดยเฉพาะ
A12: D3 | B12: รองคณบดี | C12: พิจารณาอนุมัติในสายงานที่กำกับดูแล
A13: D4 | B13: คณบดี | C13: อนุมัติเรื่องสำคัญของคณะ มีผลผูกพันด้านงบประมาณ นโยบาย หรือทรัพยากร
A14: D5 | B14: มหาวิทยาลัย/อธิการบดี/สภา | C14: อนุมัติเรื่องที่เกินอำนาจคณะ หรือเป็นไปตามข้อบังคับมหาวิทยาลัย
A16: วิธีกรอก (ใช้เวลาประมาณ 30–60 นาทีต่อหน่วยงาน)
A17: 1. เปิดชีตของหน่วยงานตนเอง (ชื่อชีตขึ้นต้นด้วยเลข 1–4) — รายการกระบวนการตั้งต้น 42 รายการ ทุกงานต้องตอบครบทุกรายการ
A18: 2. กรอกช่องสีเหลืองอ่อนทีละแถว: จำนวนรายการต่อปี, ระยะเวลาเฉลี่ย (วัน), ระยะเวลาที่ D2 ใช้ (วัน)
A19: 3. ประเมินผลกระทบ 6 ด้านด้วย Yes/No และประเมินการควบคุม (มีผู้เชี่ยวชาญตรวจอยู่แล้วหรือไม่ / D2 เพิ่มคุณค่า / D2 เคยตีกลับ)
A20: 4. เลือก 'ข้อเสนอของหัวหน้างาน' — ถ้าเลือก 'เปลี่ยนเป็นหน่วยงานผู้เชี่ยวชาญ' ต้องเลือกหน่วยงานในช่องถัดไปด้วย
A21: 5. ถ้ากระบวนการใดไม่เคยเกิดขึ้นในงานของท่าน ให้ใส่จำนวนรายการต่อปีเป็น 0 (แถวจะเป็นสีเทาขีดฆ่า และไม่ถูกนับใน Dashboard) ไม่ต้องกรอกช่องอื่น
A22: 6. มีกระบวนการเพิ่มเติม: เพิ่มชื่อในแถวว่างด้านล่างของตาราง (สูตรและ Dropdown เตรียมไว้แล้ว)
A23: 7. ดูช่อง 'ธงเตือน' — ถ้ามีข้อความ แสดงว่าข้อเสนอขัดกับระดับความเสี่ยง ควรทบทวนหรือใส่เหตุผลในช่องข้อเสนอแนะ
A25: วิธีคำนวณคะแนนความเสี่ยง (ค่าตั้งต้น ปรับได้ที่ชีต Settings)
A26: คะแนน = 25 × [งบประมาณ=Yes] + 25 × [อัตรากำลัง=Yes] + 25 × [กฎหมาย/ระเบียบ=Yes] + 25 × [ยังไม่มีผู้เชี่ยวชาญตรวจ (=No)]
A27: ระดับ: ต่ำ = คะแนนน้อยกว่า 50 | ปานกลาง = 50 ถึงน้อยกว่า 75 | สูง = ตั้งแต่ 75
A28: ผลกระทบด้านทรัพย์สิน/พัสดุ ชื่อเสียงองค์กร และนโยบาย เก็บเป็นข้อมูลประกอบ ไม่นำมาคิดคะแนนตามที่ Template กำหนด
... A31: สีที่ใช้
B32: ช่องที่ต้องกรอก
B33: สูตรอัตโนมัติ / ข้อมูลตั้งต้น (ห้ามแก้)

Sheet Dashboard
A1: Dashboard สรุปผลสำรวจ Approval Matrix (Risk-Based Approval)
A2: สรุปอัตโนมัติจากชีตของหัวหน้างานทั้ง 4 งาน — ไม่นับกระบวนการที่ไม่เคยทำ (จำนวนรายการ = 0) และร้อยละคิดจากกระบวนการที่ตอบข้อเสนอแล้ว
A4: เลือกหน่วยงานที่ต้องการดู ▶ | B4: ทั้งคณะ
A6: ภาพรวม
B7: กระบวนการทั้งหมด | D7: ตอบข้อเสนอแล้ว | F7: เสนอให้ คง D2 | H7: เสนอให้ ตัด D2 | J7: เสนอให้เปลี่ยนเป็นผู้เชี่ยวชาญ | L7: ขอหารือเพิ่มเติม
B8: =INDEX($B$13:$B$17,MATCH($B$4,$A$13:$A$17,0)) | D8: =INDEX($C$13:$C$17,MATCH($B$4,$A$13:$A$17,0)) | F8: =INDEX($D$13:$D$17,MATCH($B$4,$A$13:$A$17,0)) | H8: =INDEX($E$13:$E$17,MATCH($B$4,$A$13:$A$17,0)) | J8: =INDEX($F$13:$F$17,MATCH($B$4,$A$13:$A$17,0)) | L8: =INDEX($G$13:$G$17,MATCH($B$4,$A$13:$A$17,0))
B9: ="หน่วยงาน: "&$B$4 | D9: =IF(INDEX($B$13:$B$17,MATCH($B$4,$A$13:$A$17,0))=0,"",INDEX($C$13:$C$17,MATCH($B$4,$A$13:$A$17,0))/INDEX($B$13:$B$17,MATCH($B$4,$A$13:$A$17,0))) | F9: =INDEX($H$13:$H$17,MATCH($B$4,$A$13:$A$17,0)) | H9: =INDEX($I$13:$I$17,MATCH($B$4,$A$13:$A$17,0)) | J9: =INDEX($J$13:$J$17,MATCH($B$4,$A$13:$A$17,0)) | L9: =INDEX($K$13:$K$17,MATCH($B$4,$A$13:$A$17,0))
A10: ="หมายเหตุ: ไม่นับกระบวนการที่ไม่เคยทำ (จำนวนรายการต่อปี = 0) รวม "&(COUNTIFS('1_บริหารทั่วไป'!$C$7:$C$91,"?*",'1_บริหารทั่วไป'!$D$7:$D$91,0)+COUNTIFS('2_ยุทธศาสตร์และแผน'!$C$7:$C$91,"?*",'2_ยุทธศาสตร์และแผน'!$D$7:$D$91,0)+COUNTIFS('3_วิจัยและบริการวิชาการ'!$C$7:$C$91,"?*",'3_วิจัยและบริการวิชาการ'!$D$7:$D$91,0)+COUNTIFS('4_การศึกษาและนักศึกษา'!$C$7:$C$91,"?*",'4_การศึกษาและนักศึกษา'!$D$7:$D$91,0))&" รายการ"
A11: ตารางสรุปแยกตามหน่วยงาน
A12: หน่วยงาน | B12: กระบวนการ ทั้งหมด | C12: ตอบข้อเสนอ แล้ว | D12: คง D2 | E12: ตัด D2 | F12: เปลี่ยนเป็น ผู้เชี่ยวชาญ | G12: ขอหารือ เพิ่มเติม | H12: % คง D2 | I12: % ตัด D2 | J12: % เปลี่ยน | K12: % ขอหารือ | L12: เสี่ยงสูง | M12: เสี่ยงปานกลาง | N12: เสี่ยงต่ำ | O12: ธงเตือน | P12: วันทำการที่ ประหยัดได้/ปี | Q12: กรอกครบ (กระบวนการ)
A13: งานบริหารทั่วไป | B13: =COUNTIFS('1_บริหารทั่วไป'!$C$7:$C$91,"?*",'1_บริหารทั่วไป'!$D$7:$D$91,"<>0") | C13: =COUNTIFS('1_บริหารทั่วไป'!$C$7:$C$91,"?*",'1_บริหารทั่วไป'!$P$7:$P$91,"?*",'1_บริหารทั่วไป'!$D$7:$D$91,"<>0") | D13: =COUNTIFS('1_บริหารทั่วไป'!$P$7:$P$91,"คง D2",'1_บริหารทั่วไป'!$D$7:$D$91,"<>0") | E13: =COUNTIFS('1_บริหารทั่วไป'!$P$7:$P$91,"ตัด D2",'1_บริหารทั่วไป'!$D$7:$D$91,"<>0") | F13: =COUNTIFS('1_บริหารทั่วไป'!$P$7:$P$91,"เปลี่ยนเป็นหน่วยงานผู้เชี่ยวชาญ",'1_บริหารทั่วไป'!$D$7:$D$91,"<>0") | G13: =COUNTIFS('1_บริหารทั่วไป'!$P$7:$P$91,"ขอหารือเพิ่มเติม",'1_บริหารทั่วไป'!$D$7:$D$91,"<>0") | H13: =IF($C13=0,"",D13/$C13) | I13: =IF($C13=0,"",E13/$C13) | J13: =IF($C13=0,"",F13/$C13) | K13: =IF($C13=0,"",G13/$C13) | L13: =COUNTIFS('1_บริหารทั่วไป'!$S$7:$S$91,"สูง",'1_บริหารทั่วไป'!$D$7:$D$91,"<>0") | M13: =COUNTIFS('1_บริหารทั่วไป'!$S$7:$S$91,"ปานกลาง",'1_บริหารทั่วไป'!$D$7:$D$91,"<>0") | N13: =COUNTIFS('1_บริหารทั่วไป'!$S$7:$S$91,"ต่ำ",'1_บริหารทั่วไป'!$D$7:$D$91,"<>0") | O13: =COUNTIFS('1_บริหารทั่วไป'!$T$7:$T$91,"?*",'1_บริหารทั่วไป'!$D$7:$D$91,"<>0") | P13: =SUMIFS('1_บริหารทั่วไป'!$U$7:$U$91,'1_บริหารทั่วไป'!$D$7:$D$91,"<>0") | Q13: =COUNTIF('1_บริหารทั่วไป'!$W$7:$W$91,"✔ ครบ")
A14: งานยุทธศาสตร์และแผน | B14: =COUNTIFS('2_ยุทธศาสตร์และแผน'!$C$7:$C$91,"?*",'2_ยุทธศาสตร์และแผน'!$D$7:$D$91,"<>0") | C14: =COUNTIFS('2_ยุทธศาสตร์และแผน'!$C$7:$C$91,"?*",'2_ยุทธศาสตร์และแผน'!$P$7:$P$91,"?*",'2_ยุทธศาสตร์และแผน'!$D$7:$D$91,"<>0") | D14: =COUNTIFS('2_ยุทธศาสตร์และแผน'!$P$7:$P$91,"คง D2",'2_ยุทธศาสตร์และแผน'!$D$7:$D$91,"<>0") | E14: =COUNTIFS('2_ยุทธศาสตร์และแผน'!$P$7:$P$91,"ตัด D2",'2_ยุทธศาสตร์และแผน'!$D$7:$D$91,"<>0") | F14: =COUNTIFS('2_ยุทธศาสตร์และแผน'!$P$7:$P$91,"เปลี่ยนเป็นหน่วยงานผู้เชี่ยวชาญ",'2_ยุทธศาสตร์และแผน'!$D$7:$D$91,"<>0") | G14: =COUNTIFS('2_ยุทธศาสตร์และแผน'!$P$7:$P$91,"ขอหารือเพิ่มเติม",'2_ยุทธศาสตร์และแผน'!$D$7:$D$91,"<>0") | H14: =IF($C14=0,"",D14/$C14) | I14: =IF($C14=0,"",E14/$C14) | J14: =IF($C14=0,"",F14/$C14) | K14: =IF($C14=0,"",G14/$C14) | L14: =COUNTIFS('2_ยุทธศาสตร์และแผน'!$S$7:$S$91,"สูง",'2_ยุทธศาสตร์และแผน'!$D$7:$D$91,"<>0") | M14: =COUNTIFS('2_ยุทธศาสตร์และแผน'!$S$7:$S$91,"ปานกลาง",'2_ยุทธศาสตร์และแผน'!$D$7:$D$91,"<>0") | N14: =COUNTIFS('2_ยุทธศาสตร์และแผน'!$S$7:$S$91,"ต่ำ",'2_ยุทธศาสตร์และแผน'!$D$7:$D$91,"<>0") | O14: =COUNTIFS('2_ยุทธศาสตร์และแผน'!$T$7:$T$91,"?*",'2_ยุทธศาสตร์และแผน'!$D$7:$D$91,"<>0") | P14: =SUMIFS('2_ยุทธศาสตร์และแผน'!$U$7:$U$91,'2_ยุทธศาสตร์และแผน'!$D$7:$D$91,"<>0") | Q14: =COUNTIF('2_ยุทธศาสตร์และแผน'!$W$7:$W$91,"✔ ครบ")
A15: งานบริหารงานวิจัยและบริการวิชาการ | B15: =COUNTIFS('3_วิจัยและบริการวิชาการ'!$C$7:$C$91,"?*",'3_วิจัยและบริการวิชาการ'!$D$7:$D$91,"<>0") | C15: =COUNTIFS('3_วิจัยและบริการวิชาการ'!$C$7:$C$91,"?*",'3_วิจัยและบริการวิชาการ'!$P$7:$P$91,"?*",'3_วิจัยและบริการวิชาการ'!$D$7:$D$91,"<>0") | D15: =COUNTIFS('3_วิจัยและบริการวิชาการ'!$P$7:$P$91,"คง D2",'3_วิจัยและบริการวิชาการ'!$D$7:$D$91,"<>0") | E15: =COUNTIFS('3_วิจัยและบริการวิชาการ'!$P$7:$P$91,"ตัด D2",'3_วิจัยและบริการวิชาการ'!$D$7:$D$91,"<>0") | F15: =COUNTIFS('3_วิจัยและบริการวิชาการ'!$P$7:$P$91,"เปลี่ยนเป็นหน่วยงานผู้เชี่ยวชาญ",'3_วิจัยและบริการวิชาการ'!$D$7:$D$91,"<>0") | G15: =COUNTIFS('3_วิจัยและบริการวิชาการ'!$P$7:$P$91,"ขอหารือเพิ่มเติม",'3_วิจัยและบริการวิชาการ'!$D$7:$D$91,"<>0") | H15: =IF($C15=0,"",D15/$C15) | I15: =IF($C15=0,"",E15/$C15) | J15: =IF($C15=0,"",F15/$C15) | K15: =IF($C15=0,"",G15/$C15) | L15: =COUNTIFS('3_วิจัยและบริการวิชาการ'!$S$7:$S$91,"สูง",'3_วิจัยและบริการวิชาการ'!$D$7:$D$91,"<>0") | M15: =COUNTIFS('3_วิจัยและบริการวิชาการ'!$S$7:$S$91,"ปานกลาง",'3_วิจัยและบริการวิชาการ'!$D$7:$D$91,"<>0") | N15: =COUNTIFS('3_วิจัยและบริการวิชาการ'!$S$7:$S$91,"ต่ำ",'3_วิจัยและบริการวิชาการ'!$D$7:$D$91,"<>0") | O15: =COUNTIFS('3_วิจัยและบริการวิชาการ'!$T$7:$T$91,"?*",'3_วิจัยและบริการวิชาการ'!$D$7:$D$91,"<>0") | P15: =SUMIFS('3_วิจัยและบริการวิชาการ'!$U$7:$U$91,'3_วิจัยและบริการวิชาการ'!$D$7:$D$91,"<>0") | Q15: =COUNTIF('3_วิจัยและบริการวิชาการ'!$W$7:$W$91,"✔ ครบ")
A16: งานบริการการศึกษาและพัฒนาคุณภาพนักศึกษา | B16: =COUNTIFS('4_การศึกษาและนักศึกษา'!$C$7:$C$91,"?*",'4_การศึกษาและนักศึกษา'!$D$7:$D$91,"<>0") | C16: =COUNTIFS('4_การศึกษาและนักศึกษา'!$C$7:$C$91,"?*",'4_การศึกษาและนักศึกษา'!$P$7:$P$91,"?*",'4_การศึกษาและนักศึกษา'!$D$7:$D$91,"<>0") | D16: =COUNTIFS('4_การศึกษาและนักศึกษา'!$P$7:$P$91,"คง D2",'4_การศึกษาและนักศึกษา'!$D$7:$D$91,"<>0") | E16: =COUNTIFS('4_การศึกษาและนักศึกษา'!$P$7:$P$91,"ตัด D2",'4_การศึกษาและนักศึกษา'!$D$7:$D$91,"<>0") | F16: =COUNTIFS('4_การศึกษาและนักศึกษา'!$P$7:$P$91,"เปลี่ยนเป็นหน่วยงานผู้เชี่ยวชาญ",'4_การศึกษาและนักศึกษา'!$D$7:$D$91,"<>0") | G16: =COUNTIFS('4_การศึกษาและนักศึกษา'!$P$7:$P$91,"ขอหารือเพิ่มเติม",'4_การศึกษาและนักศึกษา'!$D$7:$D$91,"<>0") | H16: =IF($C16=0,"",D16/$C16) | I16: =IF($C16=0,"",E16/$C16) | J16: =IF($C16=0,"",F16/$C16) | K16: =IF($C16=0,"",G16/$C16) | L16: =COUNTIFS('4_การศึกษาและนักศึกษา'!$S$7:$S$91,"สูง",'4_การศึกษาและนักศึกษา'!$D$7:$D$91,"<>0") | M16: =COUNTIFS('4_การศึกษาและนักศึกษา'!$S$7:$S$91,"ปานกลาง",'4_การศึกษาและนักศึกษา'!$D$7:$D$91,"<>0") | N16: =COUNTIFS('4_การศึกษาและนักศึกษา'!$S$7:$S$91,"ต่ำ",'4_การศึกษาและนักศึกษา'!$D$7:$D$91,"<>0") | O16: =COUNTIFS('4_การศึกษาและนักศึกษา'!$T$7:$T$91,"?*",'4_การศึกษาและนักศึกษา'!$D$7:$D$91,"<>0") | P16: =SUMIFS('4_การศึกษาและนักศึกษา'!$U$7:$U$91,'4_การศึกษาและนักศึกษา'!$D$7:$D$91,"<>0") | Q16: =COUNTIF('4_การศึกษาและนักศึกษา'!$W$7:$W$91,"✔ ครบ")
A17: ทั้งคณะ | B17: =SUM(B13:B16) | C17: =SUM(C13:C16) | D17: =SUM(D13:D16) | E17: =SUM(E13:E16) | F17: =SUM(F13:F16) | G17: =SUM(G13:G16) | H17: =IF($C17=0,"",D17/$C17) | I17: =IF($C17=0,"",E17/$C17) | J17: =IF($C17=0,"",F17/$C17) | K17: =IF($C17=0,"",G17/$C17) | L17: =SUM(L13:L16) | M17: =SUM(M13:M16) | N17: =SUM(N13:N16) | O17: =SUM(O13:O16) | P17: =SUM(P13:P16) | Q17: =SUM(Q13:Q16)
A19: ความเสี่ยง × ข้อเสนอ (ทั้งคณะ) — ใช้ดูว่าข้อเสนอสอดคล้องกับระดับความเสี่ยงหรือไม่
A20: ระดับความเสี่ยง \ ข้อเสนอ | B20: คง D2 | C20: ตัด D2 | D20: เปลี่ยนเป็น ผู้เชี่ยวชาญ | E20: ขอหารือ เพิ่มเติม | F20: รวม
A21: สูง | B21: =COUNTIFS('1_บริหารทั่วไป'!$S$7:$S$91,"สูง",'1_บริหารทั่วไป'!$P$7:$P$91,"คง D2",'1_บริหารทั่วไป'!$D$7:$D$91,"<>0")+COUNTIFS('2_ยุทธศาสตร์และแผน'!$S$7:$S$91,"สูง",'2_ยุทธศาสตร์และแผน'!$P$7:$P$91,"คง D2",'2_ยุทธศาสตร์และแผน'!$D$7:$D$91,"<>0")+COUNTIFS('3_วิจัยและบริการวิชาการ'!$S$7:$S$91,"สูง",'3_วิจัยและบริการวิชาการ'!$P$7:$P$91,"คง D2",'3_วิจัยและบริการวิชาการ'!$D$7:$D$91,"<>0")+COUNTIFS('4_การศึกษาและนักศึกษา'!$S$7:$S$91,"สูง",'4_การศึกษาและนักศึกษา'!$P$7:$P$91,"คง D2",'4_การศึกษาและนักศึกษา'!$D$7:$D$91,"<>0") | C21: =COUNTIFS('1_บริหารทั่วไป'!$S$7:$S$91,"สูง",'1_บริหารทั่วไป'!$P$7:$P$91,"ตัด D2",'1_บริหารทั่วไป'!$D$7:$D$91,"<>0")+COUNTIFS('2_ยุทธศาสตร์และแผน'!$S$7:$S$91,"สูง",'2_ยุทธศาสตร์และแผน'!$P$7:$P$91,"ตัด D2",'2_ยุทธศาสตร์และแผน'!$D$7:$D$91,"<>0")+COUNTIFS('3_วิจัยและบริการวิชาการ'!$S$7:$S$91,"สูง",'3_วิจัยและบริการวิชาการ'!$P$7:$P$91,"ตัด D2",'3_วิจัยและบริการวิชาการ'!$D$7:$D$91,"<>0")+COUNTIFS('4_การศึกษาและนักศึกษา'!$S$7:$S$91,"สูง",'4_การศึกษาและนักศึกษา'!$P$7:$P$91,"ตัด D2",'4_การศึกษาและนักศึกษา'!$D$7:$D$91,"<>0") | D21: =COUNTIFS('1_บริหารทั่วไป'!$S$7:$S$91,"สูง",'1_บริหารทั่วไป'!$P$7:$P$91,"เปลี่ยนเป็นหน่วยงานผู้เชี่ยวชาญ",'1_บริหารทั่วไป'!$D$7:$D$91,"<>0")+COUNTIFS('2_ยุทธศาสตร์และแผน'!$S$7:$S$91,"สูง",'2_ยุทธศาสตร์และแผน'!$P$7:$P$91,"เปลี่ยนเป็นหน่วยงานผู้เชี่ยวชาญ",'2_ยุทธศาสตร์และแผน'!$D$7:$D$91,"<>0")+COUNTIFS('3_วิจัยและบริการวิชาการ'!$S$7:$S$91,"สูง",'3_วิจัยและบริการวิชาการ'!$P$7:$P$91,"เปลี่ยนเป็นหน่วยงานผู้เชี่ยวชาญ",'3_วิจัยและบริการวิชาการ'!$D$7:$D$91,"<>0")+COUNTIFS('4_การศึกษาและนักศึกษา'!$S$7:$S$91,"สูง",'4_การศึกษาและนักศึกษา'!$P$7:$P$91,"เปลี่ยนเป็นหน่วยงานผู้เชี่ยวชาญ",'4_การศึกษาและนักศึกษา'!$D$7:$D$91,"<>0") | E21: =COUNTIFS('1_บริหารทั่วไป'!$S$7:$S$91,"สูง",'1_บริหารทั่วไป'!$P$7:$P$91,"ขอหารือเพิ่มเติม",'1_บริหารทั่วไป'!$D$7:$D$91,"<>0")+COUNTIFS('2_ยุทธศาสตร์และแผน'!$S$7:$S$91,"สูง",'2_ยุทธศาสตร์และแผน'!$P$7:$P$91,"ขอหารือเพิ่มเติม",'2_ยุทธศาสตร์และแผน'!$D$7:$D$91,"<>0")+COUNTIFS('3_วิจัยและบริการวิชาการ'!$S$7:$S$91,"สูง",'3_วิจัยและบริการวิชาการ'!$P$7:$P$91,"ขอหารือเพิ่มเติม",'3_วิจัยและบริการวิชาการ'!$D$7:$D$91,"<>0")+COUNTIFS('4_การศึกษาและนักศึกษา'!$S$7:$S$91,"สูง",'4_การศึกษาและนักศึกษา'!$P$7:$P$91,"ขอหารือเพิ่มเติม",'4_การศึกษาและนักศึกษา'!$D$7:$D$91,"<>0") | F21: =SUM(B21:E21)
A22: ปานกลาง | B22: =COUNTIFS('1_บริหารทั่วไป'!$S$7:$S$91,"ปานกลาง",'1_บริหารทั่วไป'!$P$7:$P$91,"คง D2",'1_บริหารทั่วไป'!$D$7:$D$91,"<>0")+COUNTIFS('2_ยุทธศาสตร์และแผน'!$S$7:$S$91,"ปานกลาง",'2_ยุทธศาสตร์และแผน'!$P$7:$P$91,"คง D2",'2_ยุทธศาสตร์และแผน'!$D$7:$D$91,"<>0")+COUNTIFS('3_วิจัยและบริการวิชาการ'!$S$7:$S$91,"ปานกลาง",'3_วิจัยและบริการวิชาการ'!$P$7:$P$91,"คง D2",'3_วิจัยและบริการวิชาการ'!$D$7:$D$91,"<>0")+COUNTIFS('4_การศึกษาและนักศึกษา'!$S$7:$S$91,"ปานกลาง",'4_การศึกษาและนักศึกษา'!$P$7:$P$91,"คง D2",'4_การศึกษาและนักศึกษา'!$D$7:$D$91,"<>0") | C22: =COUNTIFS('1_บริหารทั่วไป'!$S$7:$S$91,"ปานกลาง",'1_บริหารทั่วไป'!$P$7:$P$91,"ตัด D2",'1_บริหารทั่วไป'!$D$7:$D$91,"<>0")+COUNTIFS('2_ยุทธศาสตร์และแผน'!$S$7:$S$91,"ปานกลาง",'2_ยุทธศาสตร์และแผน'!$P$7:$P$91,"ตัด D2",'2_ยุทธศาสตร์และแผน'!$D$7:$D$91,"<>0")+COUNTIFS('3_วิจัยและบริการวิชาการ'!$S$7:$S$91,"ปานกลาง",'3_วิจัยและบริการวิชาการ'!$P$7:$P$91,"ตัด D2",'3_วิจัยและบริการวิชาการ'!$D$7:$D$91,"<>0")+COUNTIFS('4_การศึกษาและนักศึกษา'!$S$7:$S$91,"ปานกลาง",'4_การศึกษาและนักศึกษา'!$P$7:$P$91,"ตัด D2",'4_การศึกษาและนักศึกษา'!$D$7:$D$91,"<>0") | D22: =COUNTIFS('1_บริหารทั่วไป'!$S$7:$S$91,"ปานกลาง",'1_บริหารทั่วไป'!$P$7:$P$91,"เปลี่ยนเป็นหน่วยงานผู้เชี่ยวชาญ",'1_บริหารทั่วไป'!$D$7:$D$91,"<>0")+COUNTIFS('2_ยุทธศาสตร์และแผน'!$S$7:$S$91,"ปานกลาง",'2_ยุทธศาสตร์และแผน'!$P$7:$P$91,"เปลี่ยนเป็นหน่วยงานผู้เชี่ยวชาญ",'2_ยุทธศาสตร์และแผน'!$D$7:$D$91,"<>0")+COUNTIFS('3_วิจัยและบริการวิชาการ'!$S$7:$S$91,"ปานกลาง",'3_วิจัยและบริการวิชาการ'!$P$7:$P$91,"เปลี่ยนเป็นหน่วยงานผู้เชี่ยวชาญ",'3_วิจัยและบริการวิชาการ'!$D$7:$D$91,"<>0")+COUNTIFS('4_การศึกษาและนักศึกษา'!$S$7:$S$91,"ปานกลาง",'4_การศึกษาและนักศึกษา'!$P$7:$P$91,"เปลี่ยนเป็นหน่วยงานผู้เชี่ยวชาญ",'4_การศึกษาและนักศึกษา'!$D$7:$D$91,"<>0") | E22: =COUNTIFS('1_บริหารทั่วไป'!$S$7:$S$91,"ปานกลาง",'1_บริหารทั่วไป'!$P$7:$P$91,"ขอหารือเพิ่มเติม",'1_บริหารทั่วไป'!$D$7:$D$91,"<>0")+COUNTIFS('2_ยุทธศาสตร์และแผน'!$S$7:$S$91,"ปานกลาง",'2_ยุทธศาสตร์และแผน'!$P$7:$P$91,"ขอหารือเพิ่มเติม",'2_ยุทธศาสตร์และแผน'!$D$7:$D$91,"<>0")+COUNTIFS('3_วิจัยและบริการวิชาการ'!$S$7:$S$91,"ปานกลาง",'3_วิจัยและบริการวิชาการ'!$P$7:$P$91,"ขอหารือเพิ่มเติม",'3_วิจัยและบริการวิชาการ'!$D$7:$D$91,"<>0")+COUNTIFS('4_การศึกษาและนักศึกษา'!$S$7:$S$91,"ปานกลาง",'4_การศึกษาและนักศึกษา'!$P$7:$P$91,"ขอหารือเพิ่มเติม",'4_การศึกษาและนักศึกษา'!$D$7:$D$91,"<>0") | F22: =SUM(B22:E22)
A23: ต่ำ | B23: =COUNTIFS('1_บริหารทั่วไป'!$S$7:$S$91,"ต่ำ",'1_บริหารทั่วไป'!$P$7:$P$91,"คง D2",'1_บริหารทั่วไป'!$D$7:$D$91,"<>0")+COUNTIFS('2_ยุทธศาสตร์และแผน'!$S$7:$S$91,"ต่ำ",'2_ยุทธศาสตร์และแผน'!$P$7:$P$91,"คง D2",'2_ยุทธศาสตร์และแผน'!$D$7:$D$91,"<>0")+COUNTIFS('3_วิจัยและบริการวิชาการ'!$S$7:$S$91,"ต่ำ",'3_วิจัยและบริการวิชาการ'!$P$7:$P$91,"คง D2",'3_วิจัยและบริการวิชาการ'!$D$7:$D$91,"<>0")+COUNTIFS('4_การศึกษาและนักศึกษา'!$S$7:$S$91,"ต่ำ",'4_การศึกษาและนักศึกษา'!$P$7:$P$91,"คง D2",'4_การศึกษาและนักศึกษา'!$D$7:$D$91,"<>0") | C23: =COUNTIFS('1_บริหารทั่วไป'!$S$7:$S$91,"ต่ำ",'1_บริหารทั่วไป'!$P$7:$P$91,"ตัด D2",'1_บริหารทั่วไป'!$D$7:$D$91,"<>0")+COUNTIFS('2_ยุทธศาสตร์และแผน'!$S$7:$S$91,"ต่ำ",'2_ยุทธศาสตร์และแผน'!$P$7:$P$91,"ตัด D2",'2_ยุทธศาสตร์และแผน'!$D$7:$D$91,"<>0")+COUNTIFS('3_วิจัยและบริการวิชาการ'!$S$7:$S$91,"ต่ำ",'3_วิจัยและบริการวิชาการ'!$P$7:$P$91,"ตัด D2",'3_วิจัยและบริการวิชาการ'!$D$7:$D$91,"<>0")+COUNTIFS('4_การศึกษาและนักศึกษา'!$S$7:$S$91,"ต่ำ",'4_การศึกษาและนักศึกษา'!$P$7:$P$91,"ตัด D2",'4_การศึกษาและนักศึกษา'!$D$7:$D$91,"<>0") | D23: =COUNTIFS('1_บริหารทั่วไป'!$S$7:$S$91,"ต่ำ",'1_บริหารทั่วไป'!$P$7:$P$91,"เปลี่ยนเป็นหน่วยงานผู้เชี่ยวชาญ",'1_บริหารทั่วไป'!$D$7:$D$91,"<>0")+COUNTIFS('2_ยุทธศาสตร์และแผน'!$S$7:$S$91,"ต่ำ",'2_ยุทธศาสตร์และแผน'!$P$7:$P$91,"เปลี่ยนเป็นหน่วยงานผู้เชี่ยวชาญ",'2_ยุทธศาสตร์และแผน'!$D$7:$D$91,"<>0")+COUNTIFS('3_วิจัยและบริการวิชาการ'!$S$7:$S$91,"ต่ำ",'3_วิจัยและบริการวิชาการ'!$P$7:$P$91,"เปลี่ยนเป็นหน่วยงานผู้เชี่ยวชาญ",'3_วิจัยและบริการวิชาการ'!$D$7:$D$91,"<>0")+COUNTIFS('4_การศึกษาและนักศึกษา'!$S$7:$S$91,"ต่ำ",'4_การศึกษาและนักศึกษา'!$P$7:$P$91,"เปลี่ยนเป็นหน่วยงานผู้เชี่ยวชาญ",'4_การศึกษาและนักศึกษา'!$D$7:$D$91,"<>0") | E23: =COUNTIFS('1_บริหารทั่วไป'!$S$7:$S$91,"ต่ำ",'1_บริหารทั่วไป'!$P$7:$P$91,"ขอหารือเพิ่มเติม",'1_บริหารทั่วไป'!$D$7:$D$91,"<>0")+COUNTIFS('2_ยุทธศาสตร์และแผน'!$S$7:$S$91,"ต่ำ",'2_ยุทธศาสตร์และแผน'!$P$7:$P$91,"ขอหารือเพิ่มเติม",'2_ยุทธศาสตร์และแผน'!$D$7:$D$91,"<>0")+COUNTIFS('3_วิจัยและบริการวิชาการ'!$S$7:$S$91,"ต่ำ",'3_วิจัยและบริการวิชาการ'!$P$7:$P$91,"ขอหารือเพิ่มเติม",'3_วิจัยและบริการวิชาการ'!$D$7:$D$91,"<>0")+COUNTIFS('4_การศึกษาและนักศึกษา'!$S$7:$S$91,"ต่ำ",'4_การศึกษาและนักศึกษา'!$P$7:$P$91,"ขอหารือเพิ่มเติม",'4_การศึกษาและนักศึกษา'!$D$7:$D$91,"<>0") | F23: =SUM(B23:E23)
A24: ช่องสีส้ม = เสี่ยงสูงแต่เสนอตัด D2 | ช่องสีเหลือง = เสี่ยงต่ำแต่เสนอคง D2 (ควรทบทวนเป็นพิเศษ)

Sheet 1_บริหารทั่วไป
A1: แบบสำรวจการปรับปรุง Approval Matrix (Risk-Based Approval)
A2: หน่วยงาน: | C2: งานบริหารทั่วไป | J2: ="กรอกครบแล้ว "&COUNTIF(W7:W91,"✔*")&" / "&COUNTIF(C7:C91,"?*")&" กระบวนการ ("&TEXT(COUNTIF(W7:W91,"✔*")/MAX(1,COUNTIF(C7:C91,"?*")),"0%")&")"
A3: วิธีกรอก: ทำตามลำดับ ①→④ จากซ้ายไปขวา เฉพาะช่องสีเหลือง | คลิกช่องใดก็ได้เพื่อดูคำอธิบาย | ช่องลำดับ: 🟩 ครบ 🟧 ยังขาด (ดูช่อง 'สถานะการกรอก') | กระบวนการที่ไม่เคยทำ ใส่จำนวนรายการ = 0 ได้เลย
A4: กระบวนการ | D4: ① ข้อมูลพื้นฐาน | G4: ② ผลกระทบ — กระบวนการนี้มีผลกระทบต่อ… (Yes/No) | M4: ③ การประเมินการควบคุม | P4: ④ ข้อเสนอของหัวหน้างาน | R4: คำนวณอัตโนมัติ (ห้ามกรอก) | V4: เพิ่มเติม (ถ้ามี) | W4: ตรวจสอบ
A5: ลำดับ | B5: กลุ่มงาน | C5: ชื่อกระบวนการ | D5: จำนวนรายการ ต่อปี | E5: ระยะเวลาดำเนินการ เฉลี่ย (วัน) | F5: ระยะเวลาที่ D2 ใช้ (วัน) | G5: งบประมาณ | H5: อัตรากำลัง | I5: กฎหมาย/ ระเบียบ | J5: ทรัพย์สิน/ พัสดุ | K5: ชื่อเสียง องค์กร | L5: นโยบาย/ ยุทธศาสตร์คณะ | M5: มีหน่วยงาน ผู้เชี่ยวชาญตรวจ อยู่แล้วหรือไม่ | N5: D2 เพิ่มคุณค่า ในระดับใด | O5: D2 เคยตรวจพบ ข้อผิดพลาด (ตีกลับ) | P5: ข้อเสนอ ของหัวหน้างาน | Q5: หน่วยงานผู้เชี่ยวชาญ (กรณีเลือกเปลี่ยน) | R5: คะแนน ความเสี่ยง | S5: ระดับ ความเสี่ยง | T5: ธงเตือน | U5: วันทำการที่ประหยัดได้ ต่อปี (ถ้าตัด D2) | V5: ข้อเสนอแนะ / แนวทางปรับปรุง Workflow | W5: สถานะการกรอก
A6: ▶ คำใบ้ | C6: ชื่อกระบวนการ (แก้ไข/เพิ่มได้) | D6: ตัวเลข เช่น 120 | E6: ตัวเลข (วัน) เช่น 7 | F6: ตัวเลข (วัน) เช่น 2 | G6: Yes = มีผลกระทบ No = ไม่มี | H6: Yes = มีผลกระทบ No = ไม่มี | I6: Yes = มีผลกระทบ No = ไม่มี | J6: Yes = มีผลกระทบ No = ไม่มี | K6: Yes = มีผลกระทบ No = ไม่มี | L6: Yes = มีผลกระทบ No = ไม่มี | M6: Yes / No | N6: เลือกจากรายการ | O6: เลือกจากรายการ | P6: เลือกจากรายการ | Q6: เลือกเมื่อ 'เปลี่ยน…' | R6: อัตโนมัติ | S6: อัตโนมัติ | T6: อัตโนมัติ | U6: อัตโนมัติ | V6: พิมพ์ข้อความ (ถ้ามี) | W6: อัตโนมัติ
A7: 1 | B7: การเงินและพัสดุ | C7: ขออนุมัติ เบิกจ่ายตามงบ | R7: =IF(COUNTA(G7:I7,M7)<4,"",Settings!$C$5*(G7="Yes")+Settings!$C$6*(H7="Yes")+Settings!$C$7*(I7="Yes")+Settings!$C$8*(M7="No")) | S7: =IF(R7="","",IF(R7>=Settings!$C$13,"สูง",IF(R7>=Settings!$C$12,"ปานกลาง","ต่ำ"))) | T7: =IF(OR(S7="",P7=""),"",IF(AND(S7="สูง",P7="ตัด D2"),"⚠ เสี่ยงสูงแต่เสนอตัด D2 — ควรทบทวน",IF(AND(S7="ต่ำ",P7="คง D2"),"ℹ เสี่ยงต่ำแต่เสนอคง D2 — อาจควบคุมเกินจำเป็น",IF(AND(P7="เปลี่ยนเป็นหน่วยงานผู้เชี่ยวชาญ",M7="No"),"⚠ เสนอโอน แต่ตอบว่ายังไม่มีผู้เชี่ยวชาญตรวจ",IF(AND(P7="เปลี่ยนเป็นหน่วยงานผู้เชี่ยวชาญ",Q7=""),"⚠ ยังไม่ระบุหน่วยงานผู้เชี่ยวชาญ",""))))) | U7: =IF(AND(P7="ตัด D2",ISNUMBER(D7),ISNUMBER(F7)),D7*F7,"") | W7: =IF(C7="","",IF(AND(ISNUMBER(D7),D7=0),"✔ ไม่เคยทำ (ข้าม)",IF(COUNTA(D7:P7)=0,"○ ยังไม่เริ่ม",IF(IF(D7="","จำนวน/ปี ","")&IF(E7="","ระยะเวลา ","")&IF(F7="","D2ใช้(วัน) ","")&IF(G7="","งบ ","")&IF(H7="","อัตรากำลัง ","")&IF(I7="","กฎหมาย ","")&IF(J7="","ทรัพย์สิน ","")&IF(K7="","ชื่อเสียง ","")&IF(L7="","นโยบาย ","")&IF(M7="","ผู้เชี่ยวชาญตรวจ ","")&IF(N7="","D2เพิ่มคุณค่า ","")&IF(O7="","D2ตีกลับ ","")&IF(P7="","ข้อเสนอ ","")&IF(AND(P7="เปลี่ยนเป็นหน่วยงานผู้เชี่ยวชาญ",Q7=""),"หน่วยงานผู้เชี่ยวชาญ ","")="","✔ ครบ","⏳ ขาด: "&TRIM(IF(D7="","จำนวน/ปี ","")&IF(E7="","ระยะเวลา ","")&IF(F7="","D2ใช้(วัน) ","")&IF(G7="","งบ ","")&IF(H7="","อัตรากำลัง ","")&IF(I7="","กฎหมาย ","")&IF(J7="","ทรัพย์สิน ","")&IF(K7="","ชื่อเสียง ","")&IF(L7="","นโยบาย ","")&IF(M7="","ผู้เชี่ยวชาญตรวจ ","")&IF(N7="","D2เพิ่มคุณค่า ","")&IF(O7="","D2ตีกลับ ","")&IF(P7="","ข้อเสนอ ","")&IF(AND(P7="เปลี่ยนเป็นหน่วยงานผู้เชี่ยวชาญ",Q7=""),"หน่วยงานผู้เชี่ยวชาญ ",""))))))
A8: 2 | B8: การเงินและพัสดุ | C8: ยืมเงินทดรองจ่าย | R8: =IF(COUNTA(G8:I8,M8)<4,"",Settings!$C$5*(G8="Yes")+Settings!$C$6*(H8="Yes")+Settings!$C$7*(I8="Yes")+Settings!$C$8*(M8="No")) | S8: =IF(R8="","",IF(R8>=Settings!$C$13,"สูง",IF(R8>=Settings!$C$12,"ปานกลาง","ต่ำ"))) | T8: =IF(OR(S8="",P8=""),"",IF(AND(S8="สูง",P8="ตัด D2"),"⚠ เสี่ยงสูงแต่เสนอตัด D2 — ควรทบทวน",IF(AND(S8="ต่ำ",P8="คง D2"),"ℹ เสี่ยงต่ำแต่เสนอคง D2 — อาจควบคุมเกินจำเป็น",IF(AND(P8="เปลี่ยนเป็นหน่วยงานผู้เชี่ยวชาญ",M8="No"),"⚠ เสนอโอน แต่ตอบว่ายังไม่มีผู้เชี่ยวชาญตรวจ",IF(AND(P8="เปลี่ยนเป็นหน่วยงานผู้เชี่ยวชาญ",Q8=""),"⚠ ยังไม่ระบุหน่วยงานผู้เชี่ยวชาญ",""))))) | U8: =IF(AND(P8="ตัด D2",ISNUMBER(D8),ISNUMBER(F8)),D8*F8,"") | W8: =IF(C8="","",IF(AND(ISNUMBER(D8),D8=0),"✔ ไม่เคยทำ (ข้าม)",IF(COUNTA(D8:P8)=0,"○ ยังไม่เริ่ม",IF(IF(D8="","จำนวน/ปี ","")&IF(E8="","ระยะเวลา ","")&IF(F8="","D2ใช้(วัน) ","")&IF(G8="","งบ ","")&IF(H8="","อัตรากำลัง ","")&IF(I8="","กฎหมาย ","")&IF(J8="","ทรัพย์สิน ","")&IF(K8="","ชื่อเสียง ","")&IF(L8="","นโยบาย ","")&IF(M8="","ผู้เชี่ยวชาญตรวจ ","")&IF(N8="","D2เพิ่มคุณค่า ","")&IF(O8="","D2ตีกลับ ","")&IF(P8="","ข้อเสนอ ","")&IF(AND(P8="เปลี่ยนเป็นหน่วยงานผู้เชี่ยวชาญ",Q8=""),"หน่วยงานผู้เชี่ยวชาญ ","")="","✔ ครบ","⏳ ขาด: "&TRIM(IF(D8="","จำนวน/ปี ","")&IF(E8="","ระยะเวลา ","")&IF(F8="","D2ใช้(วัน) ","")&IF(G8="","งบ ","")&IF(H8="","อัตรากำลัง ","")&IF(I8="","กฎหมาย ","")&IF(J8="","ทรัพย์สิน ","")&IF(K8="","ชื่อเสียง ","")&IF(L8="","นโยบาย ","")&IF(M8="","ผู้เชี่ยวชาญตรวจ ","")&IF(N8="","D2เพิ่มคุณค่า ","")&IF(O8="","D2ตีกลับ ","")&IF(P8="","ข้อเสนอ ","")&IF(AND(P8="เปลี่ยนเป็นหน่วยงานผู้เชี่ยวชาญ",Q8=""),"หน่วยงานผู้เชี่ยวชาญ ",""))))))
A9: 3 | B9: การเงินและพัสดุ | C9: ขอซื้อวัสดุสำนักงานตามแผน | R9: =IF(COUNTA(G9:I9,M9)<4,"",Settings!$C$5*(G9="Yes")+Settings!$C$6*(H9="Yes")+Settings!$C$7*(I9="Yes")+Settings!$C$8*(M9="No")) | S9: =IF(R9="","",IF(R9>=Settings!$C$13,"สูง",IF(R9>=Settings!$C$12,"ปานกลาง","ต่ำ"))) | T9: =IF(OR(S9="",P9=""),"",IF(AND(S9="สูง",P9="ตัด D2"),"⚠ เสี่ยงสูงแต่เสนอตัด D2 — ควรทบทวน",IF(AND(S9="ต่ำ",P9="คง D2"),"ℹ เสี่ยงต่ำแต่เสนอคง D2 — อาจควบคุมเกินจำเป็น",IF(AND(P9="เปลี่ยนเป็นหน่วยงานผู้เชี่ยวชาญ",M9="No"),"⚠ เสนอโอน แต่ตอบว่ายังไม่มีผู้เชี่ยวชาญตรวจ",IF(AND(P9="เปลี่ยนเป็นหน่วยงานผู้เชี่ยวชาญ",Q9=""),"⚠ ยังไม่ระบุหน่วยงานผู้เชี่ยวชาญ",""))))) | U9: =IF(AND(P9="ตัด D2",ISNUMBER(D9),ISNUMBER(F9)),D9*F9,"") | W9: =IF(C9="","",IF(AND(ISNUMBER(D9),D9=0),"✔ ไม่เคยทำ (ข้าม)",IF(COUNTA(D9:P9)=0,"○ ยังไม่เริ่ม",IF(IF(D9="","จำนวน/ปี ","")&IF(E9="","ระยะเวลา ","")&IF(F9="","D2ใช้(วัน) ","")&IF(G9="","งบ ","")&IF(H9="","อัตรากำลัง ","")&IF(I9="","กฎหมาย ","")&IF(J9="","ทรัพย์สิน ","")&IF(K9="","ชื่อเสียง ","")&IF(L9="","นโยบาย ","")&IF(M9="","ผู้เชี่ยวชาญตรวจ ","")&IF(N9="","D2เพิ่มคุณค่า ","")&IF(O9="","D2ตีกลับ ","")&IF(P9="","ข้อเสนอ ","")&IF(AND(P9="เปลี่ยนเป็นหน่วยงานผู้เชี่ยวชาญ",Q9=""),"หน่วยงานผู้เชี่ยวชาญ ","")="","✔ ครบ","⏳ ขาด: "&TRIM(IF(D9="","จำนวน/ปี ","")&IF(E9="","ระยะเวลา ","")&IF(F9="","D2ใช้(วัน) ","")&IF(G9="","งบ ","")&IF(H9="","อัตรากำลัง ","")&IF(I9="","กฎหมาย ","")&IF(J9="","ทรัพย์สิน ","")&IF(K9="","ชื่อเสียง ","")&IF(L9="","นโยบาย ","")&IF(M9="","ผู้เชี่ยวชาญตรวจ ","")&IF(N9="","D2เพิ่มคุณค่า ","")&IF(O9="","D2ตีกลับ ","")&IF(P9="","ข้อเสนอ ","")&IF(AND(P9="เปลี่ยนเป็นหน่วยงานผู้เชี่ยวชาญ",Q9=""),"หน่วยงานผู้เชี่ยวชาญ ",""))))))
A10: 4 | B10: การเงินและพัสดุ | C10: ขอซื้อวัสดุโครงการ | R10: =IF(COUNTA(G10:I10,M10)<4,"",Settings!$C$5*(G10="Yes")+Settings!$C$6*(H10="Yes")+Settings!$C$7*(I10="Yes")+Settings!$C$8*(M10="No")) | S10: =IF(R10="","",IF(R10>=Settings!$C$13,"สูง",IF(R10>=Settings!$C$12,"ปานกลาง","ต่ำ"))) | T10: =IF(OR(S10="",P10=""),"",IF(AND(S10="สูง",P10="ตัด D2"),"⚠ เสี่ยงสูงแต่เสนอตัด D2 — ควรทบทวน",IF(AND(S10="ต่ำ",P10="คง D2"),"ℹ เสี่ยงต่ำแต่เสนอคง D2 — อาจควบคุมเกินจำเป็น",IF(AND(P10="เปลี่ยนเป็นหน่วยงานผู้เชี่ยวชาญ",M10="No"),"⚠ เสนอโอน แต่ตอบว่ายังไม่มีผู้เชี่ยวชาญตรวจ",IF(AND(P10="เปลี่ยนเป็นหน่วยงานผู้เชี่ยวชาญ",Q10=""),"⚠ ยังไม่ระบุหน่วยงานผู้เชี่ยวชาญ",""))))) | U10: =IF(AND(P10="ตัด D2",ISNUMBER(D10),ISNUMBER(F10)),D10*F10,"") | W10: =IF(C10="","",IF(AND(ISNUMBER(D10),D10=0),"✔ ไม่เคยทำ (ข้าม)",IF(COUNTA(D10:P10)=0,"○ ยังไม่เริ่ม",IF(IF(D10="","จำนวน/ปี ","")&IF(E10="","ระยะเวลา ","")&IF(F10="","D2ใช้(วัน) ","")&IF(G10="","งบ ","")&IF(H10="","อัตรากำลัง ","")&IF(I10="","กฎหมาย ","")&IF(J10="","ทรัพย์สิน ","")&IF(K10="","ชื่อเสียง ","")&IF(L10="","นโยบาย ","")&IF(M10="","ผู้เชี่ยวชาญตรวจ ","")&IF(N10="","D2เพิ่มคุณค่า ","")&IF(O10="","D2ตีกลับ ","")&IF(P10="","ข้อเสนอ ","")&IF(AND(P10="เปลี่ยนเป็นหน่วยงานผู้เชี่ยวชาญ",Q10=""),"หน่วยงานผู้เชี่ยวชาญ ","")="","✔ ครบ","⏳ ขาด: "&TRIM(IF(D10="","จำนวน/ปี ","")&IF(E10="","ระยะเวลา ","")&IF(F10="","D2ใช้(วัน) ","")&IF(G10="","งบ ","")&IF(H10="","อัตรากำลัง ","")&IF(I10="","กฎหมาย ","")&IF(J10="","ทรัพย์สิน ","")&IF(K10="","ชื่อเสียง ","")&IF(L10="","นโยบาย ","")&IF(M10="","ผู้เชี่ยวชาญตรวจ ","")&IF(N10="","D2เพิ่มคุณค่า ","")&IF(O10="","D2ตีกลับ ","")&IF(P10="","ข้อเสนอ ","")&IF(AND(P10="เปลี่ยนเป็นหน่วยงานผู้เชี่ยวชาญ",Q10=""),"หน่วยงานผู้เชี่ยวชาญ ",""))))))
A11: 5 | B11: การเงินและพัสดุ | C11: ขอจ้างเหมาบริการทั่วไป | R11: =IF(COUNTA(G11:I11,M11)<4,"",Settings!$C$5*(G11="Yes")+Settings!$C$6*(H11="Yes")+Settings!$C$7*(I11="Yes")+Settings!$C$8*(M11="No")) | S11: =IF(R11="","",IF(R11>=Settings!$C$13,"สูง",IF(R11>=Settings!$C$12,"ปานกลาง","ต่ำ"))) | T11: =IF(OR(S11="",P11=""),"",IF(AND(S11="สูง",P11="ตัด D2"),"⚠ เสี่ยงสูงแต่เสนอตัด D2 — ควรทบทวน",IF(AND(S11="ต่ำ",P11="คง D2"),"ℹ เสี่ยงต่ำแต่เสนอคง D2 — อาจควบคุมเกินจำเป็น",IF(AND(P11="เปลี่ยนเป็นหน่วยงานผู้เชี่ยวชาญ",M11="No"),"⚠ เสนอโอน แต่ตอบว่ายังไม่มีผู้เชี่ยวชาญตรวจ",IF(AND(P11="เปลี่ยนเป็นหน่วยงานผู้เชี่ยวชาญ",Q11=""),"⚠ ยังไม่ระบุหน่วยงานผู้เชี่ยวชาญ",""))))) | U11: =IF(AND(P11="ตัด D2",ISNUMBER(D11),ISNUMBER(F11)),D11*F11,"") | W11: =IF(C11="","",IF(AND(ISNUMBER(D11),D11=0),"✔ ไม่เคยทำ (ข้าม)",IF(COUNTA(D11:P11)=0,"○ ยังไม่เริ่ม",IF(IF(D11="","จำนวน/ปี ","")&IF(E11="","ระยะเวลา ","")&IF(F11="","D2ใช้(วัน) ","")&IF(G11="","งบ ","")&IF(H11="","อัตรากำลัง ","")&IF(I11="","กฎหมาย ","")&IF(J11="","ทรัพย์สิน ","")&IF(K11="","ชื่อเสียง ","")&IF(L11="","นโยบาย ","")&IF(M11="","ผู้เชี่ยวชาญตรวจ ","")&IF(N11="","D2เพิ่มคุณค่า ","")&IF(O11="","D2ตีกลับ ","")&IF(P11="","ข้อเสนอ ","")&IF(AND(P11="เปลี่ยนเป็นหน่วยงานผู้เชี่ยวชาญ",Q11=""),"หน่วยงานผู้เชี่ยวชาญ ","")="","✔ ครบ","⏳ ขาด: "&TRIM(IF(D11="","จำนวน/ปี ","")&IF(E11="","ระยะเวลา ","")&IF(F11="","D2ใช้(วัน) ","")&IF(G11="","งบ ","")&IF(H11="","อัตรากำลัง ","")&IF(I11="","กฎหมาย ","")&IF(J11="","ทรัพย์สิน ","")&IF(K11="","ชื่อเสียง ","")&IF(L11="","นโยบาย ","")&IF(M11="","ผู้เชี่ยวชาญตรวจ ","")&IF(N11="","D2เพิ่มคุณค่า ","")&IF(O11="","D2ตีกลับ ","")&IF(P11="","ข้อเสนอ ","")&IF(AND(P11="เปลี่ยนเป็นหน่วยงานผู้เชี่ยวชาญ",Q11=""),"หน่วยงานผู้เชี่ยวชาญ ",""))))))
A12: 6 | B12: การเงินและพัสดุ | C12: จัดซื้อครุภัณฑ์ตามแผน | R12: =IF(COUNTA(G12:I12,M12)<4,"",Settings!$C$5*(G12="Yes")+Settings!$C$6*(H12="Yes")+Settings!$C$7*(I12="Yes")+Settings!$C$8*(M12="No")) | S12: =IF(R12="","",IF(R12>=Settings!$C$13,"สูง",IF(R12>=Settings!$C$12,"ปานกลาง","ต่ำ"))) | T12: =IF(OR(S12="",P12=""),"",IF(AND(S12="สูง",P12="ตัด D2"),"⚠ เสี่ยงสูงแต่เสนอตัด D2 — ควรทบทวน",IF(AND(S12="ต่ำ",P12="คง D2"),"ℹ เสี่ยงต่ำแต่เสนอคง D2 — อาจควบคุมเกินจำเป็น",IF(AND(P12="เปลี่ยนเป็นหน่วยงานผู้เชี่ยวชาญ",M12="No"),"⚠ เสนอโอน แต่ตอบว่ายังไม่มีผู้เชี่ยวชาญตรวจ",IF(AND(P12="เปลี่ยนเป็นหน่วยงานผู้เชี่ยวชาญ",Q12=""),"⚠ ยังไม่ระบุหน่วยงานผู้เชี่ยวชาญ",""))))) | U12: =IF(AND(P12="ตัด D2",ISNUMBER(D12),ISNUMBER(F12)),D12*F12,"") | W12: =IF(C12="","",IF(AND(ISNUMBER(D12),D12=0),"✔ ไม่เคยทำ (ข้าม)",IF(COUNTA(D12:P12)=0,"○ ยังไม่เริ่ม",IF(IF(D12="","จำนวน/ปี ","")&IF(E12="","ระยะเวลา ","")&IF(F12="","D2ใช้(วัน) ","")&IF(G12="","งบ ","")&IF(H12="","อัตรากำลัง ","")&IF(I12="","กฎหมาย ","")&IF(J12="","ทรัพย์สิน ","")&IF(K12="","ชื่อเสียง ","")&IF(L12="","นโยบาย ","")&IF(M12="","ผู้เชี่ยวชาญตรวจ ","")&IF(N12="","D2เพิ่มคุณค่า ","")&IF(O12="","D2ตีกลับ ","")&IF(P12="","ข้อเสนอ ","")&IF(AND(P12="เปลี่ยนเป็นหน่วยงานผู้เชี่ยวชาญ",Q12=""),"หน่วยงานผู้เชี่ยวชาญ ","")="","✔ ครบ","⏳ ขาด: "&TRIM(IF(D12="","จำนวน/ปี ","")&IF(E12="","ระยะเวลา ","")&IF(F12="","D2ใช้(วัน) ","")&IF(G12="","งบ ","")&IF(H12="","อัตรากำลัง ","")&IF(I12="","กฎหมาย ","")&IF(J12="","ทรัพย์สิน ","")&IF(K12="","ชื่อเสียง ","")&IF(L12="","นโยบาย ","")&IF(M12="","ผู้เชี่ยวชาญตรวจ ","")&IF(N12="","D2เพิ่มคุณค่า ","")&IF(O12="","D2ตีกลับ ","")&IF(P12="","ข้อเสนอ ","")&IF(AND(P12="เปลี่ยนเป็นหน่วยงานผู้เชี่ยวชาญ",Q12=""),"หน่วยงานผู้เชี่ยวชาญ ",""))))))
A13: 7 | B13: การเงินและพัสดุ | C13: จัดซื้อครุภัณฑ์นอกแผน | R13: =IF(COUNTA(G13:I13,M13)<4,"",Settings!$C$5*(G13="Yes")+Settings!$C$6*(H13="Yes")+Settings!$C$7*(I13="Yes")+Settings!$C$8*(M13="No")) | S13: =IF(R13="","",IF(R13>=Settings!$C$13,"สูง",IF(R13>=Settings!$C$12,"ปานกลาง","ต่ำ"))) | T13: =IF(OR(S13="",P13=""),"",IF(AND(S13="สูง",P13="ตัด D2"),"⚠ เสี่ยงสูงแต่เสนอตัด D2 — ควรทบทวน",IF(AND(S13="ต่ำ",P13="คง D2"),"ℹ เสี่ยงต่ำแต่เสนอคง D2 — อาจควบคุมเกินจำเป็น",IF(AND(P13="เปลี่ยนเป็นหน่วยงานผู้เชี่ยวชาญ",M13="No"),"⚠ เสนอโอน แต่ตอบว่ายังไม่มีผู้เชี่ยวชาญตรวจ",IF(AND(P13="เปลี่ยนเป็นหน่วยงานผู้เชี่ยวชาญ",Q13=""),"⚠ ยังไม่ระบุหน่วยงานผู้เชี่ยวชาญ",""))))) | U13: =IF(AND(P13="ตัด D2",ISNUMBER(D13),ISNUMBER(F13)),D13*F13,"") | W13: =IF(C13="","",IF(AND(ISNUMBER(D13),D13=0),"✔ ไม่เคยทำ (ข้าม)",IF(COUNTA(D13:P13)=0,"○ ยังไม่เริ่ม",IF(IF(D13="","จำนวน/ปี ","")&IF(E13="","ระยะเวลา ","")&IF(F13="","D2ใช้(วัน) ","")&IF(G13="","งบ ","")&IF(H13="","อัตรากำลัง ","")&IF(I13="","กฎหมาย ","")&IF(J13="","ทรัพย์สิน ","")&IF(K13="","ชื่อเสียง ","")&IF(L13="","นโยบาย ","")&IF(M13="","ผู้เชี่ยวชาญตรวจ ","")&IF(N13="","D2เพิ่มคุณค่า ","")&IF(O13="","D2ตีกลับ ","")&IF(P13="","ข้อเสนอ ","")&IF(AND(P13="เปลี่ยนเป็นหน่วยงานผู้เชี่ยวชาญ",Q13=""),"หน่วยงานผู้เชี่ยวชาญ ","")="","✔ ครบ","⏳ ขาด: "&TRIM(IF(D13="","จำนวน/ปี ","")&IF(E13="","ระยะเวลา ","")&IF(F13="","D2ใช้(วัน) ","")&IF(G13="","งบ ","")&IF(H13="","อัตรากำลัง ","")&IF(I13="","กฎหมาย ","")&IF(J13="","ทรัพย์สิน ","")&IF(K13="","ชื่อเสียง ","")&IF(L13="","นโยบาย ","")&IF(M13="","ผู้เชี่ยวชาญตรวจ ","")&IF(N13="","D2เพิ่มคุณค่า ","")&IF(O13="","D2ตีกลับ ","")&IF(P13="","ข้อเสนอ ","")&IF(AND(P13="เปลี่ยนเป็นหน่วยงานผู้เชี่ยวชาญ",Q13=""),"หน่วยงานผู้เชี่ยวชาญ ",""))))))
A14: 8 | B14: การเงินและพัสดุ | C14: ขออนุมัติ TOR | R14: =IF(COUNTA(G14:I14,M14)<4,"",Settings!$C$5*(G14="Yes")+Settings!$C$6*(H14="Yes")+Settings!$C$7*(I14="Yes")+Settings!$C$8*(M14="No")) | S14: =IF(R14="","",IF(R14>=Settings!$C$13,"สูง",IF(R14>=Settings!$C$12,"ปานกลาง","ต่ำ"))) | T14: =IF(OR(S14="",P14=""),"",IF(AND(S14="สูง",P14="ตัด D2"),"⚠ เสี่ยงสูงแต่เสนอตัด D2 — ควรทบทวน",IF(AND(S14="ต่ำ",P14="คง D2"),"ℹ เสี่ยงต่ำแต่เสนอคง D2 — อาจควบคุมเกินจำเป็น",IF(AND(P14="เปลี่ยนเป็นหน่วยงานผู้เชี่ยวชาญ",M14="No"),"⚠ เสนอโอน แต่ตอบว่ายังไม่มีผู้เชี่ยวชาญตรวจ",IF(AND(P14="เปลี่ยนเป็นหน่วยงานผู้เชี่ยวชาญ",Q14=""),"⚠ ยังไม่ระบุหน่วยงานผู้เชี่ยวชาญ",""))))) | U14: =IF(AND(P14="ตัด D2",ISNUMBER(D14),ISNUMBER(F14)),D14*F14,"") | W14: =IF(C14="","",IF(AND(ISNUMBER(D14),D14=0),"✔ ไม่เคยทำ (ข้าม)",IF(COUNTA(D14:P14)=0,"○ ยังไม่เริ่ม",IF(IF(D14="","จำนวน/ปี ","")&IF(E14="","ระยะเวลา ","")&IF(F14="","D2ใช้(วัน) ","")&IF(G14="","งบ ","")&IF(H14="","อัตรากำลัง ","")&IF(I14="","กฎหมาย ","")&IF(J14="","ทรัพย์สิน ","")&IF(K14="","ชื่อเสียง ","")&IF(L14="","นโยบาย ","")&IF(M14="","ผู้เชี่ยวชาญตรวจ ","")&IF(N14="","D2เพิ่มคุณค่า ","")&IF(O14="","D2ตีกลับ ","")&IF(P14="","ข้อเสนอ ","")&IF(AND(P14="เปลี่ยนเป็นหน่วยงานผู้เชี่ยวชาญ",Q14=""),"หน่วยงานผู้เชี่ยวชาญ ","")="","✔ ครบ","⏳ ขาด: "&TRIM(IF(D14="","จำนวน/ปี ","")&IF(E14="","ระยะเวลา ","")&IF(F14="","D2ใช้(วัน) ","")&IF(G14="","งบ ","")&IF(H14="","อัตรากำลัง ","")&IF(I14="","กฎหมาย ","")&IF(J14="","ทรัพย์สิน ","")&IF(K14="","ชื่อเสียง ","")&IF(L14="","นโยบาย ","")&IF(M14="","ผู้เชี่ยวชาญตรวจ ","")&IF(N14="","D2เพิ่มคุณค่า ","")&IF(O14="","D2ตีกลับ ","")&IF(P14="","ข้อเสนอ ","")&IF(AND(P14="เปลี่ยนเป็นหน่วยงานผู้เชี่ยวชาญ",Q14=""),"หน่วยงานผู้เชี่ยวชาญ ",""))))))
A15: 9 | B15: การเงินและพัสดุ | C15: ขออนุมัติราคากลาง | R15: =IF(COUNTA(G15:I15,M15)<4,"",Settings!$C$5*(G15="Yes")+Settings!$C$6*(H15="Yes")+Settings!$C$7*(I15="Yes")+Settings!$C$8*(M15="No")) | S15: =IF(R15="","",IF(R15>=Settings!$C$13,"สูง",IF(R15>=Settings!$C$12,"ปานกลาง","ต่ำ"))) | T15: =IF(OR(S15="",P15=""),"",IF(AND(S15="สูง",P15="ตัด D2"),"⚠ เสี่ยงสูงแต่เสนอตัด D2 — ควรทบทวน",IF(AND(S15="ต่ำ",P15="คง D2"),"ℹ เสี่ยงต่ำแต่เสนอคง D2 — อาจควบคุมเกินจำเป็น",IF(AND(P15="เปลี่ยนเป็นหน่วยงานผู้เชี่ยวชาญ",M15="No"),"⚠ เสนอโอน แต่ตอบว่ายังไม่มีผู้เชี่ยวชาญตรวจ",IF(AND(P15="เปลี่ยนเป็นหน่วยงานผู้เชี่ยวชาญ",Q15=""),"⚠ ยังไม่ระบุหน่วยงานผู้เชี่ยวชาญ",""))))) | U15: =IF(AND(P15="ตัด D2",ISNUMBER(D15),ISNUMBER(F15)),D15*F15,"") | W15: =IF(C15="","",IF(AND(ISNUMBER(D15),D15=0),"✔ ไม่เคยทำ (ข้าม)",IF(COUNTA(D15:P15)=0,"○ ยังไม่เริ่ม",IF(IF(D15="","จำนวน/ปี ","")&IF(E15="","ระยะเวลา ","")&IF(F15="","D2ใช้(วัน) ","")&IF(G15="","งบ ","")&IF(H15="","อัตรากำลัง ","")&IF(I15="","กฎหมาย ","")&IF(J15="","ทรัพย์สิน ","")&IF(K15="","ชื่อเสียง ","")&IF(L15="","นโยบาย ","")&IF(M15="","ผู้เชี่ยวชาญตรวจ ","")&IF(N15="","D2เพิ่มคุณค่า ","")&IF(O15="","D2ตีกลับ ","")&IF(P15="","ข้อเสนอ ","")&IF(AND(P15="เปลี่ยนเป็นหน่วยงานผู้เชี่ยวชาญ",Q15=""),"หน่วยงานผู้เชี่ยวชาญ ","")="","✔ ครบ","⏳ ขาด: "&TRIM(IF(D15="","จำนวน/ปี ","")&IF(E15="","ระยะเวลา ","")&IF(F15="","D2ใช้(วัน) ","")&IF(G15="","งบ ","")&IF(H15="","อัตรากำลัง ","")&IF(I15="","กฎหมาย ","")&IF(J15="","ทรัพย์สิน ","")&IF(K15="","ชื่อเสียง ","")&IF(L15="","นโยบาย ","")&IF(M15="","ผู้เชี่ยวชาญตรวจ ","")&IF(N15="","D2เพิ่มคุณค่า ","")&IF(O15="","D2ตีกลับ ","")&IF(P15="","ข้อเสนอ ","")&IF(AND(P15="เปลี่ยนเป็นหน่วยงานผู้เชี่ยวชาญ",Q15=""),"หน่วยงานผู้เชี่ยวชาญ ",""))))))
A16: 10 | B16: การเงินและพัสดุ | C16: แต่งตั้งคณะกรรมการจัดซื้อจัดจ้าง | R16: =IF(COUNTA(G16:I16,M16)<4,"",Settings!$C$5*(G16="Yes")+Settings!$C$6*(H16="Yes")+Settings!$C$7*(I16="Yes")+Settings!$C$8*(M16="No")) | S16: =IF(R16="","",IF(R16>=Settings!$C$13,"สูง",IF(R16>=Settings!$C$12,"ปานกลาง","ต่ำ"))) | T16: =IF(OR(S16="",P16=""),"",IF(AND(S16="สูง",P16="ตัด D2"),"⚠ เสี่ยงสูงแต่เสนอตัด D2 — ควรทบทวน",IF(AND(S16="ต่ำ",P16="คง D2"),"ℹ เสี่ยงต่ำแต่เสนอคง D2 — อาจควบคุมเกินจำเป็น",IF(AND(P16="เปลี่ยนเป็นหน่วยงานผู้เชี่ยวชาญ",M16="No"),"⚠ เสนอโอน แต่ตอบว่ายังไม่มีผู้เชี่ยวชาญตรวจ",IF(AND(P16="เปลี่ยนเป็นหน่วยงานผู้เชี่ยวชาญ",Q16=""),"⚠ ยังไม่ระบุหน่วยงานผู้เชี่ยวชาญ",""))))) | U16: =IF(AND(P16="ตัด D2",ISNUMBER(D16),ISNUMBER(F16)),D16*F16,"") | W16: =IF(C16="","",IF(AND(ISNUMBER(D16),D16=0),"✔ ไม่เคยทำ (ข้าม)",IF(COUNTA(D16:P16)=0,"○ ยังไม่เริ่ม",IF(IF(D16="","จำนวน/ปี ","")&IF(E16="","ระยะเวลา ","")&IF(F16="","D2ใช้(วัน) ","")&IF(G16="","งบ ","")&IF(H16="","อัตรากำลัง ","")&IF(I16="","กฎหมาย ","")&IF(J16="","ทรัพย์สิน ","")&IF(K16="","ชื่อเสียง ","")&IF(L16="","นโยบาย ","")&IF(M16="","ผู้เชี่ยวชาญตรวจ ","")&IF(N16="","D2เพิ่มคุณค่า ","")&IF(O16="","D2ตีกลับ ","")&IF(P16="","ข้อเสนอ ","")&IF(AND(P16="เปลี่ยนเป็นหน่วยงานผู้เชี่ยวชาญ",Q16=""),"หน่วยงานผู้เชี่ยวชาญ ","")="","✔ ครบ","⏳ ขาด: "&TRIM(IF(D16="","จำนวน/ปี ","")&IF(E16="","ระยะเวลา ","")&IF(F16="","D2ใช้(วัน) ","")&IF(G16="","งบ ","")&IF(H16="","อัตรากำลัง ","")&IF(I16="","กฎหมาย ","")&IF(J16="","ทรัพย์สิน ","")&IF(K16="","ชื่อเสียง ","")&IF(L16="","นโยบาย ","")&IF(M16="","ผู้เชี่ยวชาญตรวจ ","")&IF(N16="","D2เพิ่มคุณค่า ","")&IF(O16="","D2ตีกลับ ","")&IF(P16="","ข้อเสนอ ","")&IF(AND(P16="เปลี่ยนเป็นหน่วยงานผู้เชี่ยวชาญ",Q16=""),"หน่วยงานผู้เชี่ยวชาญ ",""))))))
A17: 11 | B17: การเงินและพัสดุ | C17: อนุมัติผลการจัดซื้อจัดจ้าง | R17: =IF(COUNTA(G17:I17,M17)<4,"",Settings!$C$5*(G17="Yes")+Settings!$C$6*(H17="Yes")+Settings!$C$7*(I17="Yes")+Settings!$C$8*(M17="No")) | S17: =IF(R17="","",IF(R17>=Settings!$C$13,"สูง",IF(R17>=Settings!$C$12,"ปานกลาง","ต่ำ"))) | T17: =IF(OR(S17="",P17=""),"",IF(AND(S17="สูง",P17="ตัด D2"),"⚠ เสี่ยงสูงแต่เสนอตัด D2 — ควรทบทวน",IF(AND(S17="ต่ำ",P17="คง D2"),"ℹ เสี่ยงต่ำแต่เสนอคง D2 — อาจควบคุมเกินจำเป็น",IF(AND(P17="เปลี่ยนเป็นหน่วยงานผู้เชี่ยวชาญ",M17="No"),"⚠ เสนอโอน แต่ตอบว่ายังไม่มีผู้เชี่ยวชาญตรวจ",IF(AND(P17="เปลี่ยนเป็นหน่วยงานผู้เชี่ยวชาญ",Q17=""),"⚠ ยังไม่ระบุหน่วยงานผู้เชี่ยวชาญ",""))))) | U17: =IF(AND(P17="ตัด D2",ISNUMBER(D17),ISNUMBER(F17)),D17*F17,"") | W17: =IF(C17="","",IF(AND(ISNUMBER(D17),D17=0),"✔ ไม่เคยทำ (ข้าม)",IF(COUNTA(D17:P17)=0,"○ ยังไม่เริ่ม",IF(IF(D17="","จำนวน/ปี ","")&IF(E17="","ระยะเวลา ","")&IF(F17="","D2ใช้(วัน) ","")&IF(G17="","งบ ","")&IF(H17="","อัตรากำลัง ","")&IF(I17="","กฎหมาย ","")&IF(J17="","ทรัพย์สิน ","")&IF(K17="","ชื่อเสียง ","")&IF(L17="","นโยบาย ","")&IF(M17="","ผู้เชี่ยวชาญตรวจ ","")&IF(N17="","D2เพิ่มคุณค่า ","")&IF(O17="","D2ตีกลับ ","")&IF(P17="","ข้อเสนอ ","")&IF(AND(P17="เปลี่ยนเป็นหน่วยงานผู้เชี่ยวชาญ",Q17=""),"หน่วยงานผู้เชี่ยวชาญ ","")="","✔ ครบ","⏳ ขาด: "&TRIM(IF(D17="","จำนวน/ปี ","")&IF(E17="","ระยะเวลา ","")&IF(F17="","D2ใช้(วัน) ","")&IF(G17="","งบ ","")&IF(H17="","อัตรากำลัง ","")&IF(I17="","กฎหมาย ","")&IF(J17="","ทรัพย์สิน ","")&IF(K17="","ชื่อเสียง ","")&IF(L17="","นโยบาย ","")&IF(M17="","ผู้เชี่ยวชาญตรวจ ","")&IF(N17="","D2เพิ่มคุณค่า ","")&IF(O17="","D2ตีกลับ ","")&IF(P17="","ข้อเสนอ ","")&IF(AND(P17="เปลี่ยนเป็นหน่วยงานผู้เชี่ยวชาญ",Q17=""),"หน่วยงานผู้เชี่ยวชาญ ",""))))))
A18: 12 | B18: การเงินและพัสดุ | C18: ขอขยายสัญญา | R18: =IF(COUNTA(G18:I18,M18)<4,"",Settings!$C$5*(G18="Yes")+Settings!$C$6*(H18="Yes")+Settings!$C$7*(I18="Yes")+Settings!$C$8*(M18="No")) | S18: =IF(R18="","",IF(R18>=Settings!$C$13,"สูง",IF(R18>=Settings!$C$12,"ปานกลาง","ต่ำ"))) | T18: =IF(OR(S18="",P18=""),"",IF(AND(S18="สูง",P18="ตัด D2"),"⚠ เสี่ยงสูงแต่เสนอตัด D2 — ควรทบทวน",IF(AND(S18="ต่ำ",P18="คง D2"),"ℹ เสี่ยงต่ำแต่เสนอคง D2 — อาจควบคุมเกินจำเป็น",IF(AND(P18="เปลี่ยนเป็นหน่วยงานผู้เชี่ยวชาญ",M18="No"),"⚠ เสนอโอน แต่ตอบว่ายังไม่มีผู้เชี่ยวชาญตรวจ",IF(AND(P18="เปลี่ยนเป็นหน่วยงานผู้เชี่ยวชาญ",Q18=""),"⚠ ยังไม่ระบุหน่วยงานผู้เชี่ยวชาญ",""))))) | U18: =IF(AND(P18="ตัด D2",ISNUMBER(D18),ISNUMBER(F18)),D18*F18,"") | W18: =IF(C18="","",IF(AND(ISNUMBER(D18),D18=0),"✔ ไม่เคยทำ (ข้าม)",IF(COUNTA(D18:P18)=0,"○ ยังไม่เริ่ม",IF(IF(D18="","จำนวน/ปี ","")&IF(E18="","ระยะเวลา ","")&IF(F18="","D2ใช้(วัน) ","")&IF(G18="","งบ ","")&IF(H18="","อัตรากำลัง ","")&IF(I18="","กฎหมาย ","")&IF(J18="","ทรัพย์สิน ","")&IF(K18="","ชื่อเสียง ","")&IF(L18="","นโยบาย ","")&IF(M18="","ผู้เชี่ยวชาญตรวจ ","")&IF(N18="","D2เพิ่มคุณค่า ","")&IF(O18="","D2ตีกลับ ","")&IF(P18="","ข้อเสนอ ","")&IF(AND(P18="เปลี่ยนเป็นหน่วยงานผู้เชี่ยวชาญ",Q18=""),"หน่วยงานผู้เชี่ยวชาญ ","")="","✔ ครบ","⏳ ขาด: "&TRIM(IF(D18="","จำนวน/ปี ","")&IF(E18="","ระยะเวลา ","")&IF(F18="","D2ใช้(วัน) ","")&IF(G18="","งบ ","")&IF(H18="","อัตรากำลัง ","")&IF(I18="","กฎหมาย ","")&IF(J18="","ทรัพย์สิน ","")&IF(K18="","ชื่อเสียง ","")&IF(L18="","นโยบาย ","")&IF(M18="","ผู้เชี่ยวชาญตรวจ ","")&IF(N18="","D2เพิ่มคุณค่า ","")&IF(O18="","D2ตีกลับ ","")&IF(P18="","ข้อเสนอ ","")&IF(AND(P18="เปลี่ยนเป็นหน่วยงานผู้เชี่ยวชาญ",Q18=""),"หน่วยงานผู้เชี่ยวชาญ ",""))))))
... A48: 42 | B48: HR: วินัย ธรรมาภิบาล และข้อร้องเรียน | C48: การอุทธรณ์ผลประเมิน | R48: =IF(COUNTA(G48:I48,M48)<4,"",Settings!$C$5*(G48="Yes")+Settings!$C$6*(H48="Yes")+Settings!$C$7*(I48="Yes")+Settings!$C$8*(M48="No")) | S48: =IF(R48="","",IF(R48>=Settings!$C$13,"สูง",IF(R48>=Settings!$C$12,"ปานกลาง","ต่ำ"))) | T48: =IF(OR(S48="",P48=""),"",IF(AND(S48="สูง",P48="ตัด D2"),"⚠ เสี่ยงสูงแต่เสนอตัด D2 — ควรทบทวน",IF(AND(S48="ต่ำ",P48="คง D2"),"ℹ เสี่ยงต่ำแต่เสนอคง D2 — อาจควบคุมเกินจำเป็น",IF(AND(P48="เปลี่ยนเป็นหน่วยงานผู้เชี่ยวชาญ",M48="No"),"⚠ เสนอโอน แต่ตอบว่ายังไม่มีผู้เชี่ยวชาญตรวจ",IF(AND(P48="เปลี่ยนเป็นหน่วยงานผู้เชี่ยวชาญ",Q48=""),"⚠ ยังไม่ระบุหน่วยงานผู้เชี่ยวชาญ",""))))) | U48: =IF(AND(P48="ตัด D2",ISNUMBER(D48),ISNUMBER(F48)),D48*F48,"") | W48: =IF(C48="","",IF(AND(ISNUMBER(D48),D48=0),"✔ ไม่เคยทำ (ข้าม)",IF(COUNTA(D48:P48)=0,"○ ยังไม่เริ่ม",IF(IF(D48="","จำนวน/ปี ","")&IF(E48="","ระยะเวลา ","")&IF(F48="","D2ใช้(วัน) ","")&IF(G48="","งบ ","")&IF(H48="","อัตรากำลัง ","")&IF(I48="","กฎหมาย ","")&IF(J48="","ทรัพย์สิน ","")&IF(K48="","ชื่อเสียง ","")&IF(L48="","นโยบาย ","")&IF(M48="","ผู้เชี่ยวชาญตรวจ ","")&IF(N48="","D2เพิ่มคุณค่า ","")&IF(O48="","D2ตีกลับ ","")&IF(P48="","ข้อเสนอ ","")&IF(AND(P48="เปลี่ยนเป็นหน่วยงานผู้เชี่ยวชาญ",Q48=""),"หน่วยงานผู้เชี่ยวชาญ ","")="","✔ ครบ","⏳ ขาด: "&TRIM(IF(D48="","จำนวน/ปี ","")&IF(E48="","ระยะเวลา ","")&IF(F48="","D2ใช้(วัน) ","")&IF(G48="","งบ ","")&IF(H48="","อัตรากำลัง ","")&IF(I48="","กฎหมาย ","")&IF(J48="","ทรัพย์สิน ","")&IF(K48="","ชื่อเสียง ","")&IF(L48="","นโยบาย ","")&IF(M48="","ผู้เชี่ยวชาญตรวจ ","")&IF(N48="","D2เพิ่มคุณค่า ","")&IF(O48="","D2ตีกลับ ","")&IF(P48="","ข้อเสนอ ","")&IF(AND(P48="เปลี่ยนเป็นหน่วยงานผู้เชี่ยวชาญ",Q48=""),"หน่วยงานผู้เชี่ยวชาญ ",""))))))
R49: =IF(COUNTA(G49:I49,M49)<4,"",Settings!$C$5*(G49="Yes")+Settings!$C$6*(H49="Yes")+Settings!$C$7*(I49="Yes")+Settings!$C$8*(M49="No")) | S49: =IF(R49="","",IF(R49>=Settings!$C$13,"สูง",IF(R49>=Settings!$C$12,"ปานกลาง","ต่ำ"))) | T49: =IF(OR(S49="",P49=""),"",IF(AND(S49="สูง",P49="ตัด D2"),"⚠ เสี่ยงสูงแต่เสนอตัด D2 — ควรทบทวน",IF(AND(S49="ต่ำ",P49="คง D2"),"ℹ เสี่ยงต่ำแต่เสนอคง D2 — อาจควบคุมเกินจำเป็น",IF(AND(P49="เปลี่ยนเป็นหน่วยงานผู้เชี่ยวชาญ",M49="No"),"⚠ เสนอโอน แต่ตอบว่ายังไม่มีผู้เชี่ยวชาญตรวจ",IF(AND(P49="เปลี่ยนเป็นหน่วยงานผู้เชี่ยวชาญ",Q49=""),"⚠ ยังไม่ระบุหน่วยงานผู้เชี่ยวชาญ",""))))) | U49: =IF(AND(P49="ตัด D2",ISNUMBER(D49),ISNUMBER(F49)),D49*F49,"") | W49: =IF(C49="","",IF(AND(ISNUMBER(D49),D49=0),"✔ ไม่เคยทำ (ข้าม)",IF(COUNTA(D49:P49)=0,"○ ยังไม่เริ่ม",IF(IF(D49="","จำนวน/ปี ","")&IF(E49="","ระยะเวลา ","")&IF(F49="","D2ใช้(วัน) ","")&IF(G49="","งบ ","")&IF(H49="","อัตรากำลัง ","")&IF(I49="","กฎหมาย ","")&IF(J49="","ทรัพย์สิน ","")&IF(K49="","ชื่อเสียง ","")&IF(L49="","นโยบาย ","")&IF(M49="","ผู้เชี่ยวชาญตรวจ ","")&IF(N49="","D2เพิ่มคุณค่า ","")&IF(O49="","D2ตีกลับ ","")&IF(P49="","ข้อเสนอ ","")&IF(AND(P49="เปลี่ยนเป็นหน่วยงานผู้เชี่ยวชาญ",Q49=""),"หน่วยงานผู้เชี่ยวชาญ ","")="","✔ ครบ","⏳ ขาด: "&TRIM(IF(D49="","จำนวน/ปี ","")&IF(E49="","ระยะเวลา ","")&IF(F49="","D2ใช้(วัน) ","")&IF(G49="","งบ ","")&IF(H49="","อัตรากำลัง ","")&IF(I49="","กฎหมาย ","")&IF(J49="","ทรัพย์สิน ","")&IF(K49="","ชื่อเสียง ","")&IF(L49="","นโยบาย ","")&IF(M49="","ผู้เชี่ยวชาญตรวจ ","")&IF(N49="","D2เพิ่มคุณค่า ","")&IF(O49="","D2ตีกลับ ","")&IF(P49="","ข้อเสนอ ","")&IF(AND(P49="เปลี่ยนเป็นหน่วยงานผู้เชี่ยวชาญ",Q49=""),"หน่วยงานผู้เชี่ยวชาญ ",""))))))
R50: =IF(COUNTA(G50:I50,M50)<4,"",Settings!$C$5*(G50="Yes")+Settings!$C$6*(H50="Yes")+Settings!$C$7*(I50="Yes")+Settings!$C$8*(M50="No")) | S50: =IF(R50="","",IF(R50>=Settings!$C$13,"สูง",IF(R50>=Settings!$C$12,"ปานกลาง","ต่ำ"))) | T50: =IF(OR(S50="",P50=""),"",IF(AND(S50="สูง",P50="ตัด D2"),"⚠ เสี่ยงสูงแต่เสนอตัด D2 — ควรทบทวน",IF(AND(S50="ต่ำ",P50="คง D2"),"ℹ เสี่ยงต่ำแต่เสนอคง D2 — อาจควบคุมเกินจำเป็น",IF(AND(P50="เปลี่ยนเป็นหน่วยงานผู้เชี่ยวชาญ",M50="No"),"⚠ เสนอโอน แต่ตอบว่ายังไม่มีผู้เชี่ยวชาญตรวจ",IF(AND(P50="เปลี่ยนเป็นหน่วยงานผู้เชี่ยวชาญ",Q50=""),"⚠ ยังไม่ระบุหน่วยงานผู้เชี่ยวชาญ",""))))) | U50: =IF(AND(P50="ตัด D2",ISNUMBER(D50),ISNUMBER(F50)),D50*F50,"") | W50: =IF(C50="","",IF(AND(ISNUMBER(D50),D50=0),"✔ ไม่เคยทำ (ข้าม)",IF(COUNTA(D50:P50)=0,"○ ยังไม่เริ่ม",IF(IF(D50="","จำนวน/ปี ","")&IF(E50="","ระยะเวลา ","")&IF(F50="","D2ใช้(วัน) ","")&IF(G50="","งบ ","")&IF(H50="","อัตรากำลัง ","")&IF(I50="","กฎหมาย ","")&IF(J50="","ทรัพย์สิน ","")&IF(K50="","ชื่อเสียง ","")&IF(L50="","นโยบาย ","")&IF(M50="","ผู้เชี่ยวชาญตรวจ ","")&IF(N50="","D2เพิ่มคุณค่า ","")&IF(O50="","D2ตีกลับ ","")&IF(P50="","ข้อเสนอ ","")&IF(AND(P50="เปลี่ยนเป็นหน่วยงานผู้เชี่ยวชาญ",Q50=""),"หน่วยงานผู้เชี่ยวชาญ ","")="","✔ ครบ","⏳ ขาด: "&TRIM(IF(D50="","จำนวน/ปี ","")&IF(E50="","ระยะเวลา ","")&IF(F50="","D2ใช้(วัน) ","")&IF(G50="","งบ ","")&IF(H50="","อัตรากำลัง ","")&IF(I50="","กฎหมาย ","")&IF(J50="","ทรัพย์สิน ","")&IF(K50="","ชื่อเสียง ","")&IF(L50="","นโยบาย ","")&IF(M50="","ผู้เชี่ยวชาญตรวจ ","")&IF(N50="","D2เพิ่มคุณค่า ","")&IF(O50="","D2ตีกลับ ","")&IF(P50="","ข้อเสนอ ","")&IF(AND(P50="เปลี่ยนเป็นหน่วยงานผู้เชี่ยวชาญ",Q50=""),"หน่วยงานผู้เชี่ยวชาญ ",""))))))
R51: =IF(COUNTA(G51:I51,M51)<4,"",Settings!$C$5*(G51="Yes")+Settings!$C$6*(H51="Yes")+Settings!$C$7*(I51="Yes")+Settings!$C$8*(M51="No")) | S51: =IF(R51="","",IF(R51>=Settings!$C$13,"สูง",IF(R51>=Settings!$C$12,"ปานกลาง","ต่ำ"))) | T51: =IF(OR(S51="",P51=""),"",IF(AND(S51="สูง",P51="ตัด D2"),"⚠ เสี่ยงสูงแต่เสนอตัด D2 — ควรทบทวน",IF(AND(S51="ต่ำ",P51="คง D2"),"ℹ เสี่ยงต่ำแต่เสนอคง D2 — อาจควบคุมเกินจำเป็น",IF(AND(P51="เปลี่ยนเป็นหน่วยงานผู้เชี่ยวชาญ",M51="No"),"⚠ เสนอโอน แต่ตอบว่ายังไม่มีผู้เชี่ยวชาญตรวจ",IF(AND(P51="เปลี่ยนเป็นหน่วยงานผู้เชี่ยวชาญ",Q51=""),"⚠ ยังไม่ระบุหน่วยงานผู้เชี่ยวชาญ",""))))) | U51: =IF(AND(P51="ตัด D2",ISNUMBER(D51),ISNUMBER(F51)),D51*F51,"") | W51: =IF(C51="","",IF(AND(ISNUMBER(D51),D51=0),"✔ ไม่เคยทำ (ข้าม)",IF(COUNTA(D51:P51)=0,"○ ยังไม่เริ่ม",IF(IF(D51="","จำนวน/ปี ","")&IF(E51="","ระยะเวลา ","")&IF(F51="","D2ใช้(วัน) ","")&IF(G51="","งบ ","")&IF(H51="","อัตรากำลัง ","")&IF(I51="","กฎหมาย ","")&IF(J51="","ทรัพย์สิน ","")&IF(K51="","ชื่อเสียง ","")&IF(L51="","นโยบาย ","")&IF(M51="","ผู้เชี่ยวชาญตรวจ ","")&IF(N51="","D2เพิ่มคุณค่า ","")&IF(O51="","D2ตีกลับ ","")&IF(P51="","ข้อเสนอ ","")&IF(AND(P51="เปลี่ยนเป็นหน่วยงานผู้เชี่ยวชาญ",Q51=""),"หน่วยงานผู้เชี่ยวชาญ ","")="","✔ ครบ","⏳ ขาด: "&TRIM(IF(D51="","จำนวน/ปี ","")&IF(E51="","ระยะเวลา ","")&IF(F51="","D2ใช้(วัน) ","")&IF(G51="","งบ ","")&IF(H51="","อัตรากำลัง ","")&IF(I51="","กฎหมาย ","")&IF(J51="","ทรัพย์สิน ","")&IF(K51="","ชื่อเสียง ","")&IF(L51="","นโยบาย ","")&IF(M51="","ผู้เชี่ยวชาญตรวจ ","")&IF(N51="","D2เพิ่มคุณค่า ","")&IF(O51="","D2ตีกลับ ","")&IF(P51="","ข้อเสนอ ","")&IF(AND(P51="เปลี่ยนเป็นหน่วยงานผู้เชี่ยวชาญ",Q51=""),"หน่วยงานผู้เชี่ยวชาญ ",""))))))
R52: =IF(COUNTA(G52:I52,M52)<4,"",Settings!$C$5*(G52="Yes")+Settings!$C$6*(H52="Yes")+Settings!$C$7*(I52="Yes")+Settings!$C$8*(M52="No")) | S52: =IF(R52="","",IF(R52>=Settings!$C$13,"สูง",IF(R52>=Settings!$C$12,"ปานกลาง","ต่ำ"))) | T52: =IF(OR(S52="",P52=""),"",IF(AND(S52="สูง",P52="ตัด D2"),"⚠ เสี่ยงสูงแต่เสนอตัด D2 — ควรทบทวน",IF(AND(S52="ต่ำ",P52="คง D2"),"ℹ เสี่ยงต่ำแต่เสนอคง D2 — อาจควบคุมเกินจำเป็น",IF(AND(P52="เปลี่ยนเป็นหน่วยงานผู้เชี่ยวชาญ",M52="No"),"⚠ เสนอโอน แต่ตอบว่ายังไม่มีผู้เชี่ยวชาญตรวจ",IF(AND(P52="เปลี่ยนเป็นหน่วยงานผู้เชี่ยวชาญ",Q52=""),"⚠ ยังไม่ระบุหน่วยงานผู้เชี่ยวชาญ",""))))) | U52: =IF(AND(P52="ตัด D2",ISNUMBER(D52),ISNUMBER(F52)),D52*F52,"") | W52: =IF(C52="","",IF(AND(ISNUMBER(D52),D52=0),"✔ ไม่เคยทำ (ข้าม)",IF(COUNTA(D52:P52)=0,"○ ยังไม่เริ่ม",IF(IF(D52="","จำนวน/ปี ","")&IF(E52="","ระยะเวลา ","")&IF(F52="","D2ใช้(วัน) ","")&IF(G52="","งบ ","")&IF(H52="","อัตรากำลัง ","")&IF(I52="","กฎหมาย ","")&IF(J52="","ทรัพย์สิน ","")&IF(K52="","ชื่อเสียง ","")&IF(L52="","นโยบาย ","")&IF(M52="","ผู้เชี่ยวชาญตรวจ ","")&IF(N52="","D2เพิ่มคุณค่า ","")&IF(O52="","D2ตีกลับ ","")&IF(P52="","ข้อเสนอ ","")&IF(AND(P52="เปลี่ยนเป็นหน่วยงานผู้เชี่ยวชาญ",Q52=""),"หน่วยงานผู้เชี่ยวชาญ ","")="","✔ ครบ","⏳ ขาด: "&TRIM(IF(D52="","จำนวน/ปี ","")&IF(E52="","ระยะเวลา ","")&IF(F52="","D2ใช้(วัน) ","")&IF(G52="","งบ ","")&IF(H52="","อัตรากำลัง ","")&IF(I52="","กฎหมาย ","")&IF(J52="","ทรัพย์สิน ","")&IF(K52="","ชื่อเสียง ","")&IF(L52="","นโยบาย ","")&IF(M52="","ผู้เชี่ยวชาญตรวจ ","")&IF(N52="","D2เพิ่มคุณค่า ","")&IF(O52="","D2ตีกลับ ","")&IF(P52="","ข้อเสนอ ","")&IF(AND(P52="เปลี่ยนเป็นหน่วยงานผู้เชี่ยวชาญ",Q52=""),"หน่วยงานผู้เชี่ยวชาญ ",""))))))
R53: =IF(COUNTA(G53:I53,M53)<4,"",Settings!$C$5*(G53="Yes")+Settings!$C$6*(H53="Yes")+Settings!$C$7*(I53="Yes")+Settings!$C$8*(M53="No")) | S53: =IF(R53="","",IF(R53>=Settings!$C$13,"สูง",IF(R53>=Settings!$C$12,"ปานกลาง","ต่ำ"))) | T53: =IF(OR(S53="",P53=""),"",IF(AND(S53="สูง",P53="ตัด D2"),"⚠ เสี่ยงสูงแต่เสนอตัด D2 — ควรทบทวน",IF(AND(S53="ต่ำ",P53="คง D2"),"ℹ เสี่ยงต่ำแต่เสนอคง D2 — อาจควบคุมเกินจำเป็น",IF(AND(P53="เปลี่ยนเป็นหน่วยงานผู้เชี่ยวชาญ",M53="No"),"⚠ เสนอโอน แต่ตอบว่ายังไม่มีผู้เชี่ยวชาญตรวจ",IF(AND(P53="เปลี่ยนเป็นหน่วยงานผู้เชี่ยวชาญ",Q53=""),"⚠ ยังไม่ระบุหน่วยงานผู้เชี่ยวชาญ",""))))) | U53: =IF(AND(P53="ตัด D2",ISNUMBER(D53),ISNUMBER(F53)),D53*F53,"") | W53: =IF(C53="","",IF(AND(ISNUMBER(D53),D53=0),"✔ ไม่เคยทำ (ข้าม)",IF(COUNTA(D53:P53)=0,"○ ยังไม่เริ่ม",IF(IF(D53="","จำนวน/ปี ","")&IF(E53="","ระยะเวลา ","")&IF(F53="","D2ใช้(วัน) ","")&IF(G53="","งบ ","")&IF(H53="","อัตรากำลัง ","")&IF(I53="","กฎหมาย ","")&IF(J53="","ทรัพย์สิน ","")&IF(K53="","ชื่อเสียง ","")&IF(L53="","นโยบาย ","")&IF(M53="","ผู้เชี่ยวชาญตรวจ ","")&IF(N53="","D2เพิ่มคุณค่า ","")&IF(O53="","D2ตีกลับ ","")&IF(P53="","ข้อเสนอ ","")&IF(AND(P53="เปลี่ยนเป็นหน่วยงานผู้เชี่ยวชาญ",Q53=""),"หน่วยงานผู้เชี่ยวชาญ ","")="","✔ ครบ","⏳ ขาด: "&TRIM(IF(D53="","จำนวน/ปี ","")&IF(E53="","ระยะเวลา ","")&IF(F53="","D2ใช้(วัน) ","")&IF(G53="","งบ ","")&IF(H53="","อัตรากำลัง ","")&IF(I53="","กฎหมาย ","")&IF(J53="","ทรัพย์สิน ","")&IF(K53="","ชื่อเสียง ","")&IF(L53="","นโยบาย ","")&IF(M53="","ผู้เชี่ยวชาญตรวจ ","")&IF(N53="","D2เพิ่มคุณค่า ","")&IF(O53="","D2ตีกลับ ","")&IF(P53="","ข้อเสนอ ","")&IF(AND(P53="เปลี่ยนเป็นหน่วยงานผู้เชี่ยวชาญ",Q53=""),"หน่วยงานผู้เชี่ยวชาญ ",""))))))
R54: =IF(COUNTA(G54:I54,M54)<4,"",Settings!$C$5*(G54="Yes")+Settings!$C$6*(H54="Yes")+Settings!$C$7*(I54="Yes")+Settings!$C$8*(M54="No")) | S54: =IF(R54="","",IF(R54>=Settings!$C$13,"สูง",IF(R54>=Settings!$C$12,"ปานกลาง","ต่ำ"))) | T54: =IF(OR(S54="",P54=""),"",IF(AND(S54="สูง",P54="ตัด D2"),"⚠ เสี่ยงสูงแต่เสนอตัด D2 — ควรทบทวน",IF(AND(S54="ต่ำ",P54="คง D2"),"ℹ เสี่ยงต่ำแต่เสนอคง D2 — อาจควบคุมเกินจำเป็น",IF(AND(P54="เปลี่ยนเป็นหน่วยงานผู้เชี่ยวชาญ",M54="No"),"⚠ เสนอโอน แต่ตอบว่ายังไม่มีผู้เชี่ยวชาญตรวจ",IF(AND(P54="เปลี่ยนเป็นหน่วยงานผู้เชี่ยวชาญ",Q54=""),"⚠ ยังไม่ระบุหน่วยงานผู้เชี่ยวชาญ",""))))) | U54: =IF(AND(P54="ตัด D2",ISNUMBER(D54),ISNUMBER(F54)),D54*F54,"") | W54: =IF(C54="","",IF(AND(ISNUMBER(D54),D54=0),"✔ ไม่เคยทำ (ข้าม)",IF(COUNTA(D54:P54)=0,"○ ยังไม่เริ่ม",IF(IF(D54="","จำนวน/ปี ","")&IF(E54="","ระยะเวลา ","")&IF(F54="","D2ใช้(วัน) ","")&IF(G54="","งบ ","")&IF(H54="","อัตรากำลัง ","")&IF(I54="","กฎหมาย ","")&IF(J54="","ทรัพย์สิน ","")&IF(K54="","ชื่อเสียง ","")&IF(L54="","นโยบาย ","")&IF(M54="","ผู้เชี่ยวชาญตรวจ ","")&IF(N54="","D2เพิ่มคุณค่า ","")&IF(O54="","D2ตีกลับ ","")&IF(P54="","ข้อเสนอ ","")&IF(AND(P54="เปลี่ยนเป็นหน่วยงานผู้เชี่ยวชาญ",Q54=""),"หน่วยงานผู้เชี่ยวชาญ ","")="","✔ ครบ","⏳ ขาด: "&TRIM(IF(D54="","จำนวน/ปี ","")&IF(E54="","ระยะเวลา ","")&IF(F54="","D2ใช้(วัน) ","")&IF(G54="","งบ ","")&IF(H54="","อัตรากำลัง ","")&IF(I54="","กฎหมาย ","")&IF(J54="","ทรัพย์สิน ","")&IF(K54="","ชื่อเสียง ","")&IF(L54="","นโยบาย ","")&IF(M54="","ผู้เชี่ยวชาญตรวจ ","")&IF(N54="","D2เพิ่มคุณค่า ","")&IF(O54="","D2ตีกลับ ","")&IF(P54="","ข้อเสนอ ","")&IF(AND(P54="เปลี่ยนเป็นหน่วยงานผู้เชี่ยวชาญ",Q54=""),"หน่วยงานผู้เชี่ยวชาญ ",""))))))
R55: =IF(COUNTA(G55:I55,M55)<4,"",Settings!$C$5*(G55="Yes")+Settings!$C$6*(H55="Yes")+Settings!$C$7*(I55="Yes")+Settings!$C$8*(M55="No")) | S55: =IF(R55="","",IF(R55>=Settings!$C$13,"สูง",IF(R55>=Settings!$C$12,"ปานกลาง","ต่ำ"))) | T55: =IF(OR(S55="",P55=""),"",IF(AND(S55="สูง",P55="ตัด D2"),"⚠ เสี่ยงสูงแต่เสนอตัด D2 — ควรทบทวน",IF(AND(S55="ต่ำ",P55="คง D2"),"ℹ เสี่ยงต่ำแต่เสนอคง D2 — อาจควบคุมเกินจำเป็น",IF(AND(P55="เปลี่ยนเป็นหน่วยงานผู้เชี่ยวชาญ",M55="No"),"⚠ เสนอโอน แต่ตอบว่ายังไม่มีผู้เชี่ยวชาญตรวจ",IF(AND(P55="เปลี่ยนเป็นหน่วยงานผู้เชี่ยวชาญ",Q55=""),"⚠ ยังไม่ระบุหน่วยงานผู้เชี่ยวชาญ",""))))) | U55: =IF(AND(P55="ตัด D2",ISNUMBER(D55),ISNUMBER(F55)),D55*F55,"") | W55: =IF(C55="","",IF(AND(ISNUMBER(D55),D55=0),"✔ ไม่เคยทำ (ข้าม)",IF(COUNTA(D55:P55)=0,"○ ยังไม่เริ่ม",IF(IF(D55="","จำนวน/ปี ","")&IF(E55="","ระยะเวลา ","")&IF(F55="","D2ใช้(วัน) ","")&IF(G55="","งบ ","")&IF(H55="","อัตรากำลัง ","")&IF(I55="","กฎหมาย ","")&IF(J55="","ทรัพย์สิน ","")&IF(K55="","ชื่อเสียง ","")&IF(L55="","นโยบาย ","")&IF(M55="","ผู้เชี่ยวชาญตรวจ ","")&IF(N55="","D2เพิ่มคุณค่า ","")&IF(O55="","D2ตีกลับ ","")&IF(P55="","ข้อเสนอ ","")&IF(AND(P55="เปลี่ยนเป็นหน่วยงานผู้เชี่ยวชาญ",Q55=""),"หน่วยงานผู้เชี่ยวชาญ ","")="","✔ ครบ","⏳ ขาด: "&TRIM(IF(D55="","จำนวน/ปี ","")&IF(E55="","ระยะเวลา ","")&IF(F55="","D2ใช้(วัน) ","")&IF(G55="","งบ ","")&IF(H55="","อัตรากำลัง ","")&IF(I55="","กฎหมาย ","")&IF(J55="","ทรัพย์สิน ","")&IF(K55="","ชื่อเสียง ","")&IF(L55="","นโยบาย ","")&IF(M55="","ผู้เชี่ยวชาญตรวจ ","")&IF(N55="","D2เพิ่มคุณค่า ","")&IF(O55="","D2ตีกลับ ","")&IF(P55="","ข้อเสนอ ","")&IF(AND(P55="เปลี่ยนเป็นหน่วยงานผู้เชี่ยวชาญ",Q55=""),"หน่วยงานผู้เชี่ยวชาญ ",""))))))
R56: =IF(COUNTA(G56:I56,M56)<4,"",Settings!$C$5*(G56="Yes")+Settings!$C$6*(H56="Yes")+Settings!$C$7*(I56="Yes")+Settings!$C$8*(M56="No")) | S56: =IF(R56="","",IF(R56>=Settings!$C$13,"สูง",IF(R56>=Settings!$C$12,"ปานกลาง","ต่ำ"))) | T56: =IF(OR(S56="",P56=""),"",IF(AND(S56="สูง",P56="ตัด D2"),"⚠ เสี่ยงสูงแต่เสนอตัด D2 — ควรทบทวน",IF(AND(S56="ต่ำ",P56="คง D2"),"ℹ เสี่ยงต่ำแต่เสนอคง D2 — อาจควบคุมเกินจำเป็น",IF(AND(P56="เปลี่ยนเป็นหน่วยงานผู้เชี่ยวชาญ",M56="No"),"⚠ เสนอโอน แต่ตอบว่ายังไม่มีผู้เชี่ยวชาญตรวจ",IF(AND(P56="เปลี่ยนเป็นหน่วยงานผู้เชี่ยวชาญ",Q56=""),"⚠ ยังไม่ระบุหน่วยงานผู้เชี่ยวชาญ",""))))) | U56: =IF(AND(P56="ตัด D2",ISNUMBER(D56),ISNUMBER(F56)),D56*F56,"") | W56: =IF(C56="","",IF(AND(ISNUMBER(D56),D56=0),"✔ ไม่เคยทำ (ข้าม)",IF(COUNTA(D56:P56)=0,"○ ยังไม่เริ่ม",IF(IF(D56="","จำนวน/ปี ","")&IF(E56="","ระยะเวลา ","")&IF(F56="","D2ใช้(วัน) ","")&IF(G56="","งบ ","")&IF(H56="","อัตรากำลัง ","")&IF(I56="","กฎหมาย ","")&IF(J56="","ทรัพย์สิน ","")&IF(K56="","ชื่อเสียง ","")&IF(L56="","นโยบาย ","")&IF(M56="","ผู้เชี่ยวชาญตรวจ ","")&IF(N56="","D2เพิ่มคุณค่า ","")&IF(O56="","D2ตีกลับ ","")&IF(P56="","ข้อเสนอ ","")&IF(AND(P56="เปลี่ยนเป็นหน่วยงานผู้เชี่ยวชาญ",Q56=""),"หน่วยงานผู้เชี่ยวชาญ ","")="","✔ ครบ","⏳ ขาด: "&TRIM(IF(D56="","จำนวน/ปี ","")&IF(E56="","ระยะเวลา ","")&IF(F56="","D2ใช้(วัน) ","")&IF(G56="","งบ ","")&IF(H56="","อัตรากำลัง ","")&IF(I56="","กฎหมาย ","")&IF(J56="","ทรัพย์สิน ","")&IF(K56="","ชื่อเสียง ","")&IF(L56="","นโยบาย ","")&IF(M56="","ผู้เชี่ยวชาญตรวจ ","")&IF(N56="","D2เพิ่มคุณค่า ","")&IF(O56="","D2ตีกลับ ","")&IF(P56="","ข้อเสนอ ","")&IF(AND(P56="เปลี่ยนเป็นหน่วยงานผู้เชี่ยวชาญ",Q56=""),"หน่วยงานผู้เชี่ยวชาญ ",""))))))
R57: =IF(COUNTA(G57:I57,M57)<4,"",Settings!$C$5*(G57="Yes")+Settings!$C$6*(H57="Yes")+Settings!$C$7*(I57="Yes")+Settings!$C$8*(M57="No")) | S57: =IF(R57="","",IF(R57>=Settings!$C$13,"สูง",IF(R57>=Settings!$C$12,"ปานกลาง","ต่ำ"))) | T57: =IF(OR(S57="",P57=""),"",IF(AND(S57="สูง",P57="ตัด D2"),"⚠ เสี่ยงสูงแต่เสนอตัด D2 — ควรทบทวน",IF(AND(S57="ต่ำ",P57="คง D2"),"ℹ เสี่ยงต่ำแต่เสนอคง D2 — อาจควบคุมเกินจำเป็น",IF(AND(P57="เปลี่ยนเป็นหน่วยงานผู้เชี่ยวชาญ",M57="No"),"⚠ เสนอโอน แต่ตอบว่ายังไม่มีผู้เชี่ยวชาญตรวจ",IF(AND(P57="เปลี่ยนเป็นหน่วยงานผู้เชี่ยวชาญ",Q57=""),"⚠ ยังไม่ระบุหน่วยงานผู้เชี่ยวชาญ",""))))) | U57: =IF(AND(P57="ตัด D2",ISNUMBER(D57),ISNUMBER(F57)),D57*F57,"") | W57: =IF(C57="","",IF(AND(ISNUMBER(D57),D57=0),"✔ ไม่เคยทำ (ข้าม)",IF(COUNTA(D57:P57)=0,"○ ยังไม่เริ่ม",IF(IF(D57="","จำนวน/ปี ","")&IF(E57="","ระยะเวลา ","")&IF(F57="","D2ใช้(วัน) ","")&IF(G57="","งบ ","")&IF(H57="","อัตรากำลัง ","")&IF(I57="","กฎหมาย ","")&IF(J57="","ทรัพย์สิน ","")&IF(K57="","ชื่อเสียง ","")&IF(L57="","นโยบาย ","")&IF(M57="","ผู้เชี่ยวชาญตรวจ ","")&IF(N57="","D2เพิ่มคุณค่า ","")&IF(O57="","D2ตีกลับ ","")&IF(P57="","ข้อเสนอ ","")&IF(AND(P57="เปลี่ยนเป็นหน่วยงานผู้เชี่ยวชาญ",Q57=""),"หน่วยงานผู้เชี่ยวชาญ ","")="","✔ ครบ","⏳ ขาด: "&TRIM(IF(D57="","จำนวน/ปี ","")&IF(E57="","ระยะเวลา ","")&IF(F57="","D2ใช้(วัน) ","")&IF(G57="","งบ ","")&IF(H57="","อัตรากำลัง ","")&IF(I57="","กฎหมาย ","")&IF(J57="","ทรัพย์สิน ","")&IF(K57="","ชื่อเสียง ","")&IF(L57="","นโยบาย ","")&IF(M57="","ผู้เชี่ยวชาญตรวจ ","")&IF(N57="","D2เพิ่มคุณค่า ","")&IF(O57="","D2ตีกลับ ","")&IF(P57="","ข้อเสนอ ","")&IF(AND(P57="เปลี่ยนเป็นหน่วยงานผู้เชี่ยวชาญ",Q57=""),"หน่วยงานผู้เชี่ยวชาญ ",""))))))
R58: =IF(COUNTA(G58:I58,M58)<4,"",Settings!$C$5*(G58="Yes")+Settings!$C$6*(H58="Yes")+Settings!$C$7*(I58="Yes")+Settings!$C$8*(M58="No")) | S58: =IF(R58="","",IF(R58>=Settings!$C$13,"สูง",IF(R58>=Settings!$C$12,"ปานกลาง","ต่ำ"))) | T58: =IF(OR(S58="",P58=""),"",IF(AND(S58="สูง",P58="ตัด D2"),"⚠ เสี่ยงสูงแต่เสนอตัด D2 — ควรทบทวน",IF(AND(S58="ต่ำ",P58="คง D2"),"ℹ เสี่ยงต่ำแต่เสนอคง D2 — อาจควบคุมเกินจำเป็น",IF(AND(P58="เปลี่ยนเป็นหน่วยงานผู้เชี่ยวชาญ",M58="No"),"⚠ เสนอโอน แต่ตอบว่ายังไม่มีผู้เชี่ยวชาญตรวจ",IF(AND(P58="เปลี่ยนเป็นหน่วยงานผู้เชี่ยวชาญ",Q58=""),"⚠ ยังไม่ระบุหน่วยงานผู้เชี่ยวชาญ",""))))) | U58: =IF(AND(P58="ตัด D2",ISNUMBER(D58),ISNUMBER(F58)),D58*F58,"") | W58: =IF(C58="","",IF(AND(ISNUMBER(D58),D58=0),"✔ ไม่เคยทำ (ข้าม)",IF(COUNTA(D58:P58)=0,"○ ยังไม่เริ่ม",IF(IF(D58="","จำนวน/ปี ","")&IF(E58="","ระยะเวลา ","")&IF(F58="","D2ใช้(วัน) ","")&IF(G58="","งบ ","")&IF(H58="","อัตรากำลัง ","")&IF(I58="","กฎหมาย ","")&IF(J58="","ทรัพย์สิน ","")&IF(K58="","ชื่อเสียง ","")&IF(L58="","นโยบาย ","")&IF(M58="","ผู้เชี่ยวชาญตรวจ ","")&IF(N58="","D2เพิ่มคุณค่า ","")&IF(O58="","D2ตีกลับ ","")&IF(P58="","ข้อเสนอ ","")&IF(AND(P58="เปลี่ยนเป็นหน่วยงานผู้เชี่ยวชาญ",Q58=""),"หน่วยงานผู้เชี่ยวชาญ ","")="","✔ ครบ","⏳ ขาด: "&TRIM(IF(D58="","จำนวน/ปี ","")&IF(E58="","ระยะเวลา ","")&IF(F58="","D2ใช้(วัน) ","")&IF(G58="","งบ ","")&IF(H58="","อัตรากำลัง ","")&IF(I58="","กฎหมาย ","")&IF(J58="","ทรัพย์สิน ","")&IF(K58="","ชื่อเสียง ","")&IF(L58="","นโยบาย ","")&IF(M58="","ผู้เชี่ยวชาญตรวจ ","")&IF(N58="","D2เพิ่มคุณค่า ","")&IF(O58="","D2ตีกลับ ","")&IF(P58="","ข้อเสนอ ","")&IF(AND(P58="เปลี่ยนเป็นหน่วยงานผู้เชี่ยวชาญ",Q58=""),"หน่วยงานผู้เชี่ยวชาญ ",""))))))
R59: =IF(COUNTA(G59:I59,M59)<4,"",Settings!$C$5*(G59="Yes")+Settings!$C$6*(H59="Yes")+Settings!$C$7*(I59="Yes")+Settings!$C$8*(M59="No")) | S59: =IF(R59="","",IF(R59>=Settings!$C$13,"สูง",IF(R59>=Settings!$C$12,"ปานกลาง","ต่ำ"))) | T59: =IF(OR(S59="",P59=""),"",IF(AND(S59="สูง",P59="ตัด D2"),"⚠ เสี่ยงสูงแต่เสนอตัด D2 — ควรทบทวน",IF(AND(S59="ต่ำ",P59="คง D2"),"ℹ เสี่ยงต่ำแต่เสนอคง D2 — อาจควบคุมเกินจำเป็น",IF(AND(P59="เปลี่ยนเป็นหน่วยงานผู้เชี่ยวชาญ",M59="No"),"⚠ เสนอโอน แต่ตอบว่ายังไม่มีผู้เชี่ยวชาญตรวจ",IF(AND(P59="เปลี่ยนเป็นหน่วยงานผู้เชี่ยวชาญ",Q59=""),"⚠ ยังไม่ระบุหน่วยงานผู้เชี่ยวชาญ",""))))) | U59: =IF(AND(P59="ตัด D2",ISNUMBER(D59),ISNUMBER(F59)),D59*F59,"") | W59: =IF(C59="","",IF(AND(ISNUMBER(D59),D59=0),"✔ ไม่เคยทำ (ข้าม)",IF(COUNTA(D59:P59)=0,"○ ยังไม่เริ่ม",IF(IF(D59="","จำนวน/ปี ","")&IF(E59="","ระยะเวลา ","")&IF(F59="","D2ใช้(วัน) ","")&IF(G59="","งบ ","")&IF(H59="","อัตรากำลัง ","")&IF(I59="","กฎหมาย ","")&IF(J59="","ทรัพย์สิน ","")&IF(K59="","ชื่อเสียง ","")&IF(L59="","นโยบาย ","")&IF(M59="","ผู้เชี่ยวชาญตรวจ ","")&IF(N59="","D2เพิ่มคุณค่า ","")&IF(O59="","D2ตีกลับ ","")&IF(P59="","ข้อเสนอ ","")&IF(AND(P59="เปลี่ยนเป็นหน่วยงานผู้เชี่ยวชาญ",Q59=""),"หน่วยงานผู้เชี่ยวชาญ ","")="","✔ ครบ","⏳ ขาด: "&TRIM(IF(D59="","จำนวน/ปี ","")&IF(E59="","ระยะเวลา ","")&IF(F59="","D2ใช้(วัน) ","")&IF(G59="","งบ ","")&IF(H59="","อัตรากำลัง ","")&IF(I59="","กฎหมาย ","")&IF(J59="","ทรัพย์สิน ","")&IF(K59="","ชื่อเสียง ","")&IF(L59="","นโยบาย ","")&IF(M59="","ผู้เชี่ยวชาญตรวจ ","")&IF(N59="","D2เพิ่มคุณค่า ","")&IF(O59="","D2ตีกลับ ","")&IF(P59="","ข้อเสนอ ","")&IF(AND(P59="เปลี่ยนเป็นหน่วยงานผู้เชี่ยวชาญ",Q59=""),"หน่วยงานผู้เชี่ยวชาญ ",""))))))
